Workbook

Sheet CT_SL_DT
Q1: Chọn tháng → | R1: 12
A2: CÔNG TY CỔ PHẦN XÂY DỰNG NGÔ QUYỀN | H2: CỘNG HÒA XÃ HỘI CHỦ NGHĨA VIỆT NAM | Q2: Chọn năm → | R2: 2025
A3: BAN CHỈ HUY CÔNG TRƯỜNG | H3: Độc lập - Tự do - Hạnh phúc
A4: ="CHỈ TIÊU SẢN LƯỢNG, DOANH THU THÁNG "&R1&" NĂM "&R2 -> CHỈ TIÊU SẢN LƯỢNG, DOANH THU THÁNG 12 NĂM 2025
A5: DỰ ÁN : KHU NHÀ Ở TẠI PHƯỜNG TRẠI CHUỐI
A6: ="Tháng "&R1&" Năm "&R2 -> Tháng 12 Năm 2025
A7: Đơn vị: đồng
A8: STT | B8: Danh mục | C8: Giá trị dự toán phần thô 2024 hoặc Quyết toán: | D8: Sản lượng luỹ kế đầu kỳ | E8: Doanh thu luỹ kế đầu kỳ | F8: Sản lượng kỳ này | H8: Doanh thu kỳ này | J8: Sản lượng trát | K8: Doanh thu trát | L8: Doanh thu cần thực hiện theo tiến độ | M8: Công việc cần hoàn thành theo doanh thu lũy kế | N8: Tiến độ thực tế (Khung bê tông cốt thép) | O8: Tình trạng thực hiện doanh thu | P8: Ghi chú
F9: Chỉ tiêu | G9: Thực hiện | H9: Chỉ tiêu | I9: Thực hiện
A11: I | B11: Trại chuối GĐ 1
A12: A | D12: 0 | E12: 0
A13: 1 | B13: Lô 5A | C13: {=IFERROR(INDEX(Data_CT!G$2:G$327,MATCH($R$2&$R$1&$B13,Data_CT!$B$2:$B$327&Data_CT!$A$2:$A$327&Data_CT!$F$2:$F$327,0)),"")} -> 1140788000 | D13: {=IFERROR(INDEX(Data_CT!H$2:H$327,MATCH($R$2&$R$1&$B13,Data_CT!$B$2:$B$327&Data_CT!$A$2:$A$327&Data_CT!$F$2:$F$327,0)),"")} -> 853717725 | E13: {=IFERROR(INDEX(Data_CT!I$2:I$327,MATCH($R$2&$R$1&$B13,Data_CT!$B$2:$B$327&Data_CT!$A$2:$A$327&Data_CT!$F$2:$F$327,0)),"")} -> 700000000 | F13: {=IFERROR(INDEX(Data_CT!J$2:J$327,MATCH($R$2&$R$1&$B13,Data_CT!$B$2:$B$327&Data_CT!$A$2:$A$327&Data_CT!$F$2:$F$327,0)),"")} -> 0 | G13: {=IFERROR(INDEX(Data_CT!K$2:K$327,MATCH($R$2&$R$1&$B13,Data_CT!$B$2:$B$327&Data_CT!$A$2:$A$327&Data_CT!$F$2:$F$327,0)),"")} -> 173974500 | H13: {=IFERROR(INDEX(Data_CT!L$2:L$327,MATCH($R$2&$R$1&$B13,Data_CT!$B$2:$B$327&Data_CT!$A$2:$A$327&Data_CT!$F$2:$F$327,0)),"")} -> 300000000 | I13: {=IFERROR(INDEX(Data_CT!M$2:M$327,MATCH($R$2&$R$1&$B13,Data_CT!$B$2:$B$327&Data_CT!$A$2:$A$327&Data_CT!$F$2:$F$327,0)),"")} -> 300000000 | J13: {=IFERROR(INDEX(Data_CT!N$2:N$327,MATCH($R$2&$R$1&$B13,Data_CT!$B$2:$B$327&Data_CT!$A$2:$A$327&Data_CT!$F$2:$F$327,0)),"")} -> 0 | K13: {=IFERROR(INDEX(Data_CT!O$2:O$327,MATCH($R$2&$R$1&$B13,Data_CT!$B$2:$B$327&Data_CT!$A$2:$A$327&Data_CT!$F$2:$F$327,0)),"")} -> 0 | M13: {=IFERROR(INDEX(Data_CT!P$2:P$327,MATCH($R$2&$R$1&$B13,Data_CT!$B$2:$B$327&Data_CT!$A$2:$A$327&Data_CT!$F$2:$F$327,0)),"")} | N13: {=IFERROR(INDEX(Data_CT!Q$2:Q$327,MATCH($R$2&$R$1&$B13,Data_CT!$B$2:$B$327&Data_CT!$A$2:$A$327&Data_CT!$F$2:$F$327,0)),"")} -> Mái tầng 3 | P13: {=IFERROR(INDEX(Data_CT!R$2:R$327,MATCH($R$2&$R$1&$B13,Data_CT!$B$2:$B$327&Data_CT!$A$2:$A$327&Data_CT!$F$2:$F$327,0)),"")} -> Xong khung BTCT
A14: 2 | B14: Lô 9A | C14: {=IFERROR(INDEX(Data_CT!G$2:G$327,MATCH($R$2&$R$1&$B14,Data_CT!$B$2:$B$327&Data_CT!$A$2:$A$327&Data_CT!$F$2:$F$327,0)),"")} -> 1118543000 | D14: {=IFERROR(INDEX(Data_CT!H$2:H$327,MATCH($R$2&$R$1&$B14,Data_CT!$B$2:$B$327&Data_CT!$A$2:$A$327&Data_CT!$F$2:$F$327,0)),"")} -> 1118543000 | E14: {=IFERROR(INDEX(Data_CT!I$2:I$327,MATCH($R$2&$R$1&$B14,Data_CT!$B$2:$B$327&Data_CT!$A$2:$A$327&Data_CT!$F$2:$F$327,0)),"")} -> 1118000000 | F14: {=IFERROR(INDEX(Data_CT!J$2:J$327,MATCH($R$2&$R$1&$B14,Data_CT!$B$2:$B$327&Data_CT!$A$2:$A$327&Data_CT!$F$2:$F$327,0)),"")} -> 0 | G14: {=IFERROR(INDEX(Data_CT!K$2:K$327,MATCH($R$2&$R$1&$B14,Data_CT!$B$2:$B$327&Data_CT!$A$2:$A$327&Data_CT!$F$2:$F$327,0)),"")} -> 0 | H14: {=IFERROR(INDEX(Data_CT!L$2:L$327,MATCH($R$2&$R$1&$B14,Data_CT!$B$2:$B$327&Data_CT!$A$2:$A$327&Data_CT!$F$2:$F$327,0)),"")} -> 0 | I14: {=IFERROR(INDEX(Data_CT!M$2:M$327,MATCH($R$2&$R$1&$B14,Data_CT!$B$2:$B$327&Data_CT!$A$2:$A$327&Data_CT!$F$2:$F$327,0)),"")} -> 0 | J14: {=IFERROR(INDEX(Data_CT!N$2:N$327,MATCH($R$2&$R$1&$B14,Data_CT!$B$2:$B$327&Data_CT!$A$2:$A$327&Data_CT!$F$2:$F$327,0)),"")} -> 1.3825648e+08 | K14: {=IFERROR(INDEX(Data_CT!O$2:O$327,MATCH($R$2&$R$1&$B14,Data_CT!$B$2:$B$327&Data_CT!$A$2:$A$327&Data_CT!$F$2:$F$327,0)),"")} -> 138256070 | M14: {=IFERROR(INDEX(Data_CT!P$2:P$327,MATCH($R$2&$R$1&$B14,Data_CT!$B$2:$B$327&Data_CT!$A$2:$A$327&Data_CT!$F$2:$F$327,0)),"")} -> 0 | N14: {=IFERROR(INDEX(Data_CT!Q$2:Q$327,MATCH($R$2&$R$1&$B14,Data_CT!$B$2:$B$327&Data_CT!$A$2:$A$327&Data_CT!$F$2:$F$327,0)),"")} -> 0 | P14: {=IFERROR(INDEX(Data_CT!R$2:R$327,MATCH($R$2&$R$1&$B14,Data_CT!$B$2:$B$327&Data_CT!$A$2:$A$327&Data_CT!$F$2:$F$327,0)),"")} -> Xong khung BTCT
A15: 3 | B15: Lô 12A | C15: {=IFERROR(INDEX(Data_CT!G$2:G$327,MATCH($R$2&$R$1&$B15,Data_CT!$B$2:$B$327&Data_CT!$A$2:$A$327&Data_CT!$F$2:$F$327,0)),"")} -> 1161338000 | D15: {=IFERROR(INDEX(Data_CT!H$2:H$327,MATCH($R$2&$R$1&$B15,Data_CT!$B$2:$B$327&Data_CT!$A$2:$A$327&Data_CT!$F$2:$F$327,0)),"")} -> 1161338000 | E15: {=IFERROR(INDEX(Data_CT!I$2:I$327,MATCH($R$2&$R$1&$B15,Data_CT!$B$2:$B$327&Data_CT!$A$2:$A$327&Data_CT!$F$2:$F$327,0)),"")} -> 1161338000 | F15: {=IFERROR(INDEX(Data_CT!J$2:J$327,MATCH($R$2&$R$1&$B15,Data_CT!$B$2:$B$327&Data_CT!$A$2:$A$327&Data_CT!$F$2:$F$327,0)),"")} -> 0 | G15: {=IFERROR(INDEX(Data_CT!K$2:K$327,MATCH($R$2&$R$1&$B15,Data_CT!$B$2:$B$327&Data_CT!$A$2:$A$327&Data_CT!$F$2:$F$327,0)),"")} -> 0 | H15: {=IFERROR(INDEX(Data_CT!L$2:L$327,MATCH($R$2&$R$1&$B15,Data_CT!$B$2:$B$327&Data_CT!$A$2:$A$327&Data_CT!$F$2:$F$327,0)),"")} -> 0 | I15: {=IFERROR(INDEX(Data_CT!M$2:M$327,MATCH($R$2&$R$1&$B15,Data_CT!$B$2:$B$327&Data_CT!$A$2:$A$327&Data_CT!$F$2:$F$327,0)),"")} -> 0 | J15: {=IFERROR(INDEX(Data_CT!N$2:N$327,MATCH($R$2&$R$1&$B15,Data_CT!$B$2:$B$327&Data_CT!$A$2:$A$327&Data_CT!$F$2:$F$327,0)),"")} -> 28072222 | K15: {=IFERROR(INDEX(Data_CT!O$2:O$327,MATCH($R$2&$R$1&$B15,Data_CT!$B$2:$B$327&Data_CT!$A$2:$A$327&Data_CT!$F$2:$F$327,0)),"")} -> 28072132 | M15: {=IFERROR(INDEX(Data_CT!P$2:P$327,MATCH($R$2&$R$1&$B15,Data_CT!$B$2:$B$327&Data_CT!$A$2:$A$327&Data_CT!$F$2:$F$327,0)),"")} -> 1161338000 | N15: {=IFERROR(INDEX(Data_CT!Q$2:Q$327,MATCH($R$2&$R$1&$B15,Data_CT!$B$2:$B$327&Data_CT!$A$2:$A$327&Data_CT!$F$2:$F$327,0)),"")} -> 0 | P15: {=IFERROR(INDEX(Data_CT!R$2:R$327,MATCH($R$2&$R$1&$B15,Data_CT!$B$2:$B$327&Data_CT!$A$2:$A$327&Data_CT!$F$2:$F$327,0)),"")} -> 0
A16: 4 | B16: Lô 13A | C16: {=IFERROR(INDEX(Data_CT!G$2:G$327,MATCH($R$2&$R$1&$B16,Data_CT!$B$2:$B$327&Data_CT!$A$2:$A$327&Data_CT!$F$2:$F$327,0)),"")} -> 1129099000 | D16: {=IFERROR(INDEX(Data_CT!H$2:H$327,MATCH($R$2&$R$1&$B16,Data_CT!$B$2:$B$327&Data_CT!$A$2:$A$327&Data_CT!$F$2:$F$327,0)),"")} -> 489397680 | E16: {=IFERROR(INDEX(Data_CT!I$2:I$327,MATCH($R$2&$R$1&$B16,Data_CT!$B$2:$B$327&Data_CT!$A$2:$A$327&Data_CT!$F$2:$F$327,0)),"")} -> 800000000 | F16: {=IFERROR(INDEX(Data_CT!J$2:J$327,MATCH($R$2&$R$1&$B16,Data_CT!$B$2:$B$327&Data_CT!$A$2:$A$327&Data_CT!$F$2:$F$327,0)),"")} -> 0 | G16: {=IFERROR(INDEX(Data_CT!K$2:K$327,MATCH($R$2&$R$1&$B16,Data_CT!$B$2:$B$327&Data_CT!$A$2:$A$327&Data_CT!$F$2:$F$327,0)),"")} -> 186300000 | H16: {=IFERROR(INDEX(Data_CT!L$2:L$327,MATCH($R$2&$R$1&$B16,Data_CT!$B$2:$B$327&Data_CT!$A$2:$A$327&Data_CT!$F$2:$F$327,0)),"")} -> 0 | I16: {=IFERROR(INDEX(Data_CT!M$2:M$327,MATCH($R$2&$R$1&$B16,Data_CT!$B$2:$B$327&Data_CT!$A$2:$A$327&Data_CT!$F$2:$F$327,0)),"")} -> 0 | J16: {=IFERROR(INDEX(Data_CT!N$2:N$327,MATCH($R$2&$R$1&$B16,Data_CT!$B$2:$B$327&Data_CT!$A$2:$A$327&Data_CT!$F$2:$F$327,0)),"")} -> 0 | K16: {=IFERROR(INDEX(Data_CT!O$2:O$327,MATCH($R$2&$R$1&$B16,Data_CT!$B$2:$B$327&Data_CT!$A$2:$A$327&Data_CT!$F$2:$F$327,0)),"")} -> 0 | M16: {=IFERROR(INDEX(Data_CT!P$2:P$327,MATCH($R$2&$R$1&$B16,Data_CT!$B$2:$B$327&Data_CT!$A$2:$A$327&Data_CT!$F$2:$F$327,0)),"")} | N16: {=IFERROR(INDEX(Data_CT!Q$2:Q$327,MATCH($R$2&$R$1&$B16,Data_CT!$B$2:$B$327&Data_CT!$A$2:$A$327&Data_CT!$F$2:$F$327,0)),"")} -> Mái tầng 1 | P16: {=IFERROR(INDEX(Data_CT!R$2:R$327,MATCH($R$2&$R$1&$B16,Data_CT!$B$2:$B$327&Data_CT!$A$2:$A$327&Data_CT!$F$2:$F$327,0)),"")} -> Xong khung BTCT
A17: 5 | B17: Lô 14A | C17: {=IFERROR(INDEX(Data_CT!G$2:G$327,MATCH($R$2&$R$1&$B17,Data_CT!$B$2:$B$327&Data_CT!$A$2:$A$327&Data_CT!$F$2:$F$327,0)),"")} -> 1129099000 | D17: {=IFERROR(INDEX(Data_CT!H$2:H$327,MATCH($R$2&$R$1&$B17,Data_CT!$B$2:$B$327&Data_CT!$A$2:$A$327&Data_CT!$F$2:$F$327,0)),"")} -> 649826280 | E17: {=IFERROR(INDEX(Data_CT!I$2:I$327,MATCH($R$2&$R$1&$B17,Data_CT!$B$2:$B$327&Data_CT!$A$2:$A$327&Data_CT!$F$2:$F$327,0)),"")} -> 400000000 | F17: {=IFERROR(INDEX(Data_CT!J$2:J$327,MATCH($R$2&$R$1&$B17,Data_CT!$B$2:$B$327&Data_CT!$A$2:$A$327&Data_CT!$F$2:$F$327,0)),"")} -> 0 | G17: {=IFERROR(INDEX(Data_CT!K$2:K$327,MATCH($R$2&$R$1&$B17,Data_CT!$B$2:$B$327&Data_CT!$A$2:$A$327&Data_CT!$F$2:$F$327,0)),"")} -> 0 | H17: {=IFERROR(INDEX(Data_CT!L$2:L$327,MATCH($R$2&$R$1&$B17,Data_CT!$B$2:$B$327&Data_CT!$A$2:$A$327&Data_CT!$F$2:$F$327,0)),"")} -> 300000000 | I17: {=IFERROR(INDEX(Data_CT!M$2:M$327,MATCH($R$2&$R$1&$B17,Data_CT!$B$2:$B$327&Data_CT!$A$2:$A$327&Data_CT!$F$2:$F$327,0)),"")} -> 0 | J17: {=IFERROR(INDEX(Data_CT!N$2:N$327,MATCH($R$2&$R$1&$B17,Data_CT!$B$2:$B$327&Data_CT!$A$2:$A$327&Data_CT!$F$2:$F$327,0)),"")} -> 0 | K17: {=IFERROR(INDEX(Data_CT!O$2:O$327,MATCH($R$2&$R$1&$B17,Data_CT!$B$2:$B$327&Data_CT!$A$2:$A$327&Data_CT!$F$2:$F$327,0)),"")} -> 0 | M17: {=IFERROR(INDEX(Data_CT!P$2:P$327,MATCH($R$2&$R$1&$B17,Data_CT!$B$2:$B$327&Data_CT!$A$2:$A$327&Data_CT!$F$2:$F$327,0)),"")} | N17: {=IFERROR(INDEX(Data_CT!Q$2:Q$327,MATCH($R$2&$R$1&$B17,Data_CT!$B$2:$B$327&Data_CT!$A$2:$A$327&Data_CT!$F$2:$F$327,0)),"")} -> Mái tầng 1 | P17: {=IFERROR(INDEX(Data_CT!R$2:R$327,MATCH($R$2&$R$1&$B17,Data_CT!$B$2:$B$327&Data_CT!$A$2:$A$327&Data_CT!$F$2:$F$327,0)),"")} -> Mái Tầng 1
A18: B | D18: 0 | E18: 0 | O18: =_xludf.LET( TienDaDong, E18+I18, TienYeuCau, L18, TrangThai_P, P18, KetQua, IF(OR(TienYeuCau=0, TienYeuCau=""), "", IF(TienDaDong >= TienYeuCau, "✅ Đủ tiền", _xludf.LET( MaLo, B18, TienDoHienTai_Text, M18, Diem_HienTai, _xludf.IFNA(VLOOKUP(TienDoHienTai_Text, CauHinh!$A:$B, 2, 0), 0), Moc_Diem_1, VLOOKUP(MaLo, 'TIẾN ĐỘ NỘP TIỀN'!$B:$Z, 23, 0), Moc_Diem_2, VLOOKUP(MaLo, 'TIẾN ĐỘ NỘP TIỀN'!$B:$Z, 24, 0), Moc_Diem_3, VLOOKUP(MaLo, 'TIẾN ĐỘ NỘP TIỀN'!$B:$Z, 25, 0), TenDot, IF(TrangThai_P="Đã quyết toán", "Quyết toán", _xludf.IFS(Diem_HienTai >= (Moc_Diem_3 - 10), "Đợt 4", Diem_HienTai >= (Moc_Diem_2 - 10), "Đợt 3", Diem_HienTai >= (Moc_Diem_1 - 10), "Đợt 2", TRUE, "Đợt 1") ), "⚠️ Cần nộp " & TenDot & " (Còn thiếu " & TEXT(TienYeuCau - TienDaDong, "#,##0") & ") - Tổng cần nộp: " & TEXT(TienYeuCau, "#,##0") ))), KetQua ) -> #NAME?
A19: 1 | B19: Lô 1B | C19: {=IFERROR(INDEX(Data_CT!G$2:G$327,MATCH($R$2&$R$1&$B19,Data_CT!$B$2:$B$327&Data_CT!$A$2:$A$327&Data_CT!$F$2:$F$327,0)),"")} -> 1295727000 | D19: {=IFERROR(INDEX(Data_CT!H$2:H$327,MATCH($R$2&$R$1&$B19,Data_CT!$B$2:$B$327&Data_CT!$A$2:$A$327&Data_CT!$F$2:$F$327,0)),"")} -> 1295727000 | E19: {=IFERROR(INDEX(Data_CT!I$2:I$327,MATCH($R$2&$R$1&$B19,Data_CT!$B$2:$B$327&Data_CT!$A$2:$A$327&Data_CT!$F$2:$F$327,0)),"")} -> 1150000000 | F19: {=IFERROR(INDEX(Data_CT!J$2:J$327,MATCH($R$2&$R$1&$B19,Data_CT!$B$2:$B$327&Data_CT!$A$2:$A$327&Data_CT!$F$2:$F$327,0)),"")} -> 0 | G19: {=IFERROR(INDEX(Data_CT!K$2:K$327,MATCH($R$2&$R$1&$B19,Data_CT!$B$2:$B$327&Data_CT!$A$2:$A$327&Data_CT!$F$2:$F$327,0)),"")} -> 0 | H19: {=IFERROR(INDEX(Data_CT!L$2:L$327,MATCH($R$2&$R$1&$B19,Data_CT!$B$2:$B$327&Data_CT!$A$2:$A$327&Data_CT!$F$2:$F$327,0)),"")} -> 145727000 | I19: {=IFERROR(INDEX(Data_CT!M$2:M$327,MATCH($R$2&$R$1&$B19,Data_CT!$B$2:$B$327&Data_CT!$A$2:$A$327&Data_CT!$F$2:$F$327,0)),"")} -> 0 | J19: {=IFERROR(INDEX(Data_CT!N$2:N$327,MATCH($R$2&$R$1&$B19,Data_CT!$B$2:$B$327&Data_CT!$A$2:$A$327&Data_CT!$F$2:$F$327,0)),"")} -> 205662963 | K19: {=IFERROR(INDEX(Data_CT!O$2:O$327,MATCH($R$2&$R$1&$B19,Data_CT!$B$2:$B$327&Data_CT!$A$2:$A$327&Data_CT!$F$2:$F$327,0)),"")} -> 100000000 | M19: {=IFERROR(INDEX(Data_CT!P$2:P$327,MATCH($R$2&$R$1&$B19,Data_CT!$B$2:$B$327&Data_CT!$A$2:$A$327&Data_CT!$F$2:$F$327,0)),"")} -> 1295727000 | N19: {=IFERROR(INDEX(Data_CT!Q$2:Q$327,MATCH($R$2&$R$1&$B19,Data_CT!$B$2:$B$327&Data_CT!$A$2:$A$327&Data_CT!$F$2:$F$327,0)),"")} -> 0 | P19: {=IFERROR(INDEX(Data_CT!R$2:R$327,MATCH($R$2&$R$1&$B19,Data_CT!$B$2:$B$327&Data_CT!$A$2:$A$327&Data_CT!$F$2:$F$327,0)),"")} -> 0
A20: 2 | B20: Lô 2B | C20: {=IFERROR(INDEX(Data_CT!G$2:G$327,MATCH($R$2&$R$1&$B20,Data_CT!$B$2:$B$327&Data_CT!$A$2:$A$327&Data_CT!$F$2:$F$327,0)),"")} -> 1280505000 | D20: {=IFERROR(INDEX(Data_CT!H$2:H$327,MATCH($R$2&$R$1&$B20,Data_CT!$B$2:$B$327&Data_CT!$A$2:$A$327&Data_CT!$F$2:$F$327,0)),"")} -> 0 | E20: {=IFERROR(INDEX(Data_CT!I$2:I$327,MATCH($R$2&$R$1&$B20,Data_CT!$B$2:$B$327&Data_CT!$A$2:$A$327&Data_CT!$F$2:$F$327,0)),"")} -> 0 | F20: {=IFERROR(INDEX(Data_CT!J$2:J$327,MATCH($R$2&$R$1&$B20,Data_CT!$B$2:$B$327&Data_CT!$A$2:$A$327&Data_CT!$F$2:$F$327,0)),"")} -> 0 | G20: {=IFERROR(INDEX(Data_CT!K$2:K$327,MATCH($R$2&$R$1&$B20,Data_CT!$B$2:$B$327&Data_CT!$A$2:$A$327&Data_CT!$F$2:$F$327,0)),"")} -> 0 | H20: {=IFERROR(INDEX(Data_CT!L$2:L$327,MATCH($R$2&$R$1&$B20,Data_CT!$B$2:$B$327&Data_CT!$A$2:$A$327&Data_CT!$F$2:$F$327,0)),"")} -> 300000000 | I20: {=IFERROR(INDEX(Data_CT!M$2:M$327,MATCH($R$2&$R$1&$B20,Data_CT!$B$2:$B$327&Data_CT!$A$2:$A$327&Data_CT!$F$2:$F$327,0)),"")} -> 0 | J20: {=IFERROR(INDEX(Data_CT!N$2:N$327,MATCH($R$2&$R$1&$B20,Data_CT!$B$2:$B$327&Data_CT!$A$2:$A$327&Data_CT!$F$2:$F$327,0)),"")} -> 0 | K20: {=IFERROR(INDEX(Data_CT!O$2:O$327,MATCH($R$2&$R$1&$B20,Data_CT!$B$2:$B$327&Data_CT!$A$2:$A$327&Data_CT!$F$2:$F$327,0)),"")} -> 0 | M20: {=IFERROR(INDEX(Data_CT!P$2:P$327,MATCH($R$2&$R$1&$B20,Data_CT!$B$2:$B$327&Data_CT!$A$2:$A$327&Data_CT!$F$2:$F$327,0)),"")} -> 0 | N20: {=IFERROR(INDEX(Data_CT!Q$2:Q$327,MATCH($R$2&$R$1&$B20,Data_CT!$B$2:$B$327&Data_CT!$A$2:$A$327&Data_CT!$F$2:$F$327,0)),"")} -> 0 | P20: {=IFERROR(INDEX(Data_CT!R$2:R$327,MATCH($R$2&$R$1&$B20,Data_CT!$B$2:$B$327&Data_CT!$A$2:$A$327&Data_CT!$F$2:$F$327,0)),"")} -> 0
A21: 3 | B21: Lô 3B | C21: {=IFERROR(INDEX(Data_CT!G$2:G$327,MATCH($R$2&$R$1&$B21,Data_CT!$B$2:$B$327&Data_CT!$A$2:$A$327&Data_CT!$F$2:$F$327,0)),"")} -> 1629894000 | D21: {=IFERROR(INDEX(Data_CT!H$2:H$327,MATCH($R$2&$R$1&$B21,Data_CT!$B$2:$B$327&Data_CT!$A$2:$A$327&Data_CT!$F$2:$F$327,0)),"")} -> 1629894000 | E21: {=IFERROR(INDEX(Data_CT!I$2:I$327,MATCH($R$2&$R$1&$B21,Data_CT!$B$2:$B$327&Data_CT!$A$2:$A$327&Data_CT!$F$2:$F$327,0)),"")} -> 1629894000 | F21: {=IFERROR(INDEX(Data_CT!J$2:J$327,MATCH($R$2&$R$1&$B21,Data_CT!$B$2:$B$327&Data_CT!$A$2:$A$327&Data_CT!$F$2:$F$327,0)),"")} -> 0 | G21: {=IFERROR(INDEX(Data_CT!K$2:K$327,MATCH($R$2&$R$1&$B21,Data_CT!$B$2:$B$327&Data_CT!$A$2:$A$327&Data_CT!$F$2:$F$327,0)),"")} -> 0 | H21: {=IFERROR(INDEX(Data_CT!L$2:L$327,MATCH($R$2&$R$1&$B21,Data_CT!$B$2:$B$327&Data_CT!$A$2:$A$327&Data_CT!$F$2:$F$327,0)),"")} -> 0 | I21: {=IFERROR(INDEX(Data_CT!M$2:M$327,MATCH($R$2&$R$1&$B21,Data_CT!$B$2:$B$327&Data_CT!$A$2:$A$327&Data_CT!$F$2:$F$327,0)),"")} -> 0 | J21: {=IFERROR(INDEX(Data_CT!N$2:N$327,MATCH($R$2&$R$1&$B21,Data_CT!$B$2:$B$327&Data_CT!$A$2:$A$327&Data_CT!$F$2:$F$327,0)),"")} -> 1.3494444e+08 | K21: {=IFERROR(INDEX(Data_CT!O$2:O$327,MATCH($R$2&$R$1&$B21,Data_CT!$B$2:$B$327&Data_CT!$A$2:$A$327&Data_CT!$F$2:$F$327,0)),"")} -> 134944617 | M21: {=IFERROR(INDEX(Data_CT!P$2:P$327,MATCH($R$2&$R$1&$B21,Data_CT!$B$2:$B$327&Data_CT!$A$2:$A$327&Data_CT!$F$2:$F$327,0)),"")} -> 1629894000 | N21: {=IFERROR(INDEX(Data_CT!Q$2:Q$327,MATCH($R$2&$R$1&$B21,Data_CT!$B$2:$B$327&Data_CT!$A$2:$A$327&Data_CT!$F$2:$F$327,0)),"")} -> 0 | P21: {=IFERROR(INDEX(Data_CT!R$2:R$327,MATCH($R$2&$R$1&$B21,Data_CT!$B$2:$B$327&Data_CT!$A$2:$A$327&Data_CT!$F$2:$F$327,0)),"")} -> 0
A22: 4 | B22: Lô 4B | C22: {=IFERROR(INDEX(Data_CT!G$2:G$327,MATCH($R$2&$R$1&$B22,Data_CT!$B$2:$B$327&Data_CT!$A$2:$A$327&Data_CT!$F$2:$F$327,0)),"")} -> 1323642000 | D22: {=IFERROR(INDEX(Data_CT!H$2:H$327,MATCH($R$2&$R$1&$B22,Data_CT!$B$2:$B$327&Data_CT!$A$2:$A$327&Data_CT!$F$2:$F$327,0)),"")} -> 1323642000 | E22: {=IFERROR(INDEX(Data_CT!I$2:I$327,MATCH($R$2&$R$1&$B22,Data_CT!$B$2:$B$327&Data_CT!$A$2:$A$327&Data_CT!$F$2:$F$327,0)),"")} -> 1300000000 | F22: {=IFERROR(INDEX(Data_CT!J$2:J$327,MATCH($R$2&$R$1&$B22,Data_CT!$B$2:$B$327&Data_CT!$A$2:$A$327&Data_CT!$F$2:$F$327,0)),"")} -> 0 | G22: {=IFERROR(INDEX(Data_CT!K$2:K$327,MATCH($R$2&$R$1&$B22,Data_CT!$B$2:$B$327&Data_CT!$A$2:$A$327&Data_CT!$F$2:$F$327,0)),"")} -> 0 | H22: {=IFERROR(INDEX(Data_CT!L$2:L$327,MATCH($R$2&$R$1&$B22,Data_CT!$B$2:$B$327&Data_CT!$A$2:$A$327&Data_CT!$F$2:$F$327,0)),"")} -> 0 | I22: {=IFERROR(INDEX(Data_CT!M$2:M$327,MATCH($R$2&$R$1&$B22,Data_CT!$B$2:$B$327&Data_CT!$A$2:$A$327&Data_CT!$F$2:$F$327,0)),"")} -> 0 | J22: {=IFERROR(INDEX(Data_CT!N$2:N$327,MATCH($R$2&$R$1&$B22,Data_CT!$B$2:$B$327&Data_CT!$A$2:$A$327&Data_CT!$F$2:$F$327,0)),"")} -> 0 | K22: {=IFERROR(INDEX(Data_CT!O$2:O$327,MATCH($R$2&$R$1&$B22,Data_CT!$B$2:$B$327&Data_CT!$A$2:$A$327&Data_CT!$F$2:$F$327,0)),"")} -> 0 | M22: {=IFERROR(INDEX(Data_CT!P$2:P$327,MATCH($R$2&$R$1&$B22,Data_CT!$B$2:$B$327&Data_CT!$A$2:$A$327&Data_CT!$F$2:$F$327,0)),"")} | N22: {=IFERROR(INDEX(Data_CT!Q$2:Q$327,MATCH($R$2&$R$1&$B22,Data_CT!$B$2:$B$327&Data_CT!$A$2:$A$327&Data_CT!$F$2:$F$327,0)),"")} -> Xong khung BTCT | P22: {=IFERROR(INDEX(Data_CT!R$2:R$327,MATCH($R$2&$R$1&$B22,Data_CT!$B$2:$B$327&Data_CT!$A$2:$A$327&Data_CT!$F$2:$F$327,0)),"")} -> Xong khung BTCT
A23: 5 | B23: Lô 6B | C23: {=IFERROR(INDEX(Data_CT!G$2:G$327,MATCH($R$2&$R$1&$B23,Data_CT!$B$2:$B$327&Data_CT!$A$2:$A$327&Data_CT!$F$2:$F$327,0)),"")} -> 1352546000 | D23: {=IFERROR(INDEX(Data_CT!H$2:H$327,MATCH($R$2&$R$1&$B23,Data_CT!$B$2:$B$327&Data_CT!$A$2:$A$327&Data_CT!$F$2:$F$327,0)),"")} -> 1352546000 | E23: {=IFERROR(INDEX(Data_CT!I$2:I$327,MATCH($R$2&$R$1&$B23,Data_CT!$B$2:$B$327&Data_CT!$A$2:$A$327&Data_CT!$F$2:$F$327,0)),"")} -> 1300000000 | F23: {=IFERROR(INDEX(Data_CT!J$2:J$327,MATCH($R$2&$R$1&$B23,Data_CT!$B$2:$B$327&Data_CT!$A$2:$A$327&Data_CT!$F$2:$F$327,0)),"")} -> 0 | G23: {=IFERROR(INDEX(Data_CT!K$2:K$327,MATCH($R$2&$R$1&$B23,Data_CT!$B$2:$B$327&Data_CT!$A$2:$A$327&Data_CT!$F$2:$F$327,0)),"")} -> 0 | H23: {=IFERROR(INDEX(Data_CT!L$2:L$327,MATCH($R$2&$R$1&$B23,Data_CT!$B$2:$B$327&Data_CT!$A$2:$A$327&Data_CT!$F$2:$F$327,0)),"")} -> 0 | I23: {=IFERROR(INDEX(Data_CT!M$2:M$327,MATCH($R$2&$R$1&$B23,Data_CT!$B$2:$B$327&Data_CT!$A$2:$A$327&Data_CT!$F$2:$F$327,0)),"")} -> 0 | J23: {=IFERROR(INDEX(Data_CT!N$2:N$327,MATCH($R$2&$R$1&$B23,Data_CT!$B$2:$B$327&Data_CT!$A$2:$A$327&Data_CT!$F$2:$F$327,0)),"")} -> 0 | K23: {=IFERROR(INDEX(Data_CT!O$2:O$327,MATCH($R$2&$R$1&$B23,Data_CT!$B$2:$B$327&Data_CT!$A$2:$A$327&Data_CT!$F$2:$F$327,0)),"")} -> 0 | M23: {=IFERROR(INDEX(Data_CT!P$2:P$327,MATCH($R$2&$R$1&$B23,Data_CT!$B$2:$B$327&Data_CT!$A$2:$A$327&Data_CT!$F$2:$F$327,0)),"")} | N23: {=IFERROR(INDEX(Data_CT!Q$2:Q$327,MATCH($R$2&$R$1&$B23,Data_CT!$B$2:$B$327&Data_CT!$A$2:$A$327&Data_CT!$F$2:$F$327,0)),"")} -> Xong khung BTCT | P23: {=IFERROR(INDEX(Data_CT!R$2:R$327,MATCH($R$2&$R$1&$B23,Data_CT!$B$2:$B$327&Data_CT!$A$2:$A$327&Data_CT!$F$2:$F$327,0)),"")} -> Xong khung BTCT | Q23: đđặt
A24: 6 | B24: Lô 7B | C24: {=IFERROR(INDEX(Data_CT!G$2:G$327,MATCH($R$2&$R$1&$B24,Data_CT!$B$2:$B$327&Data_CT!$A$2:$A$327&Data_CT!$F$2:$F$327,0)),"")} -> 1221751000 | D24: {=IFERROR(INDEX(Data_CT!H$2:H$327,MATCH($R$2&$R$1&$B24,Data_CT!$B$2:$B$327&Data_CT!$A$2:$A$327&Data_CT!$F$2:$F$327,0)),"")} -> 1221751000 | E24: {=IFERROR(INDEX(Data_CT!I$2:I$327,MATCH($R$2&$R$1&$B24,Data_CT!$B$2:$B$327&Data_CT!$A$2:$A$327&Data_CT!$F$2:$F$327,0)),"")} -> 1100000000 | F24: {=IFERROR(INDEX(Data_CT!J$2:J$327,MATCH($R$2&$R$1&$B24,Data_CT!$B$2:$B$327&Data_CT!$A$2:$A$327&Data_CT!$F$2:$F$327,0)),"")} -> 0 | G24: {=IFERROR(INDEX(Data_CT!K$2:K$327,MATCH($R$2&$R$1&$B24,Data_CT!$B$2:$B$327&Data_CT!$A$2:$A$327&Data_CT!$F$2:$F$327,0)),"")} -> 0 | H24: {=IFERROR(INDEX(Data_CT!L$2:L$327,MATCH($R$2&$R$1&$B24,Data_CT!$B$2:$B$327&Data_CT!$A$2:$A$327&Data_CT!$F$2:$F$327,0)),"")} -> 200000000 | I24: {=IFERROR(INDEX(Data_CT!M$2:M$327,MATCH($R$2&$R$1&$B24,Data_CT!$B$2:$B$327&Data_CT!$A$2:$A$327&Data_CT!$F$2:$F$327,0)),"")} -> 0 | J24: {=IFERROR(INDEX(Data_CT!N$2:N$327,MATCH($R$2&$R$1&$B24,Data_CT!$B$2:$B$327&Data_CT!$A$2:$A$327&Data_CT!$F$2:$F$327,0)),"")} -> 56776852 | K24: {=IFERROR(INDEX(Data_CT!O$2:O$327,MATCH($R$2&$R$1&$B24,Data_CT!$B$2:$B$327&Data_CT!$A$2:$A$327&Data_CT!$F$2:$F$327,0)),"")} -> 0 | M24: {=IFERROR(INDEX(Data_CT!P$2:P$327,MATCH($R$2&$R$1&$B24,Data_CT!$B$2:$B$327&Data_CT!$A$2:$A$327&Data_CT!$F$2:$F$327,0)),"")} | N24: {=IFERROR(INDEX(Data_CT!Q$2:Q$327,MATCH($R$2&$R$1&$B24,Data_CT!$B$2:$B$327&Data_CT!$A$2:$A$327&Data_CT!$F$2:$F$327,0)),"")} -> Xong khung BTCT | P24: {=IFERROR(INDEX(Data_CT!R$2:R$327,MATCH($R$2&$R$1&$B24,Data_CT!$B$2:$B$327&Data_CT!$A$2:$A$327&Data_CT!$F$2:$F$327,0)),"")} -> Xong khung BTCT
A25: 7 | B25: Lô 8B | C25: {=IFERROR(INDEX(Data_CT!G$2:G$327,MATCH($R$2&$R$1&$B25,Data_CT!$B$2:$B$327&Data_CT!$A$2:$A$327&Data_CT!$F$2:$F$327,0)),"")} -> 1195530000 | D25: {=IFERROR(INDEX(Data_CT!H$2:H$327,MATCH($R$2&$R$1&$B25,Data_CT!$B$2:$B$327&Data_CT!$A$2:$A$327&Data_CT!$F$2:$F$327,0)),"")} -> 1195530000 | E25: {=IFERROR(INDEX(Data_CT!I$2:I$327,MATCH($R$2&$R$1&$B25,Data_CT!$B$2:$B$327&Data_CT!$A$2:$A$327&Data_CT!$F$2:$F$327,0)),"")} -> 1195530000 | F25: {=IFERROR(INDEX(Data_CT!J$2:J$327,MATCH($R$2&$R$1&$B25,Data_CT!$B$2:$B$327&Data_CT!$A$2:$A$327&Data_CT!$F$2:$F$327,0)),"")} -> 0 | G25: {=IFERROR(INDEX(Data_CT!K$2:K$327,MATCH($R$2&$R$1&$B25,Data_CT!$B$2:$B$327&Data_CT!$A$2:$A$327&Data_CT!$F$2:$F$327,0)),"")} -> 0 | H25: {=IFERROR(INDEX(Data_CT!L$2:L$327,MATCH($R$2&$R$1&$B25,Data_CT!$B$2:$B$327&Data_CT!$A$2:$A$327&Data_CT!$F$2:$F$327,0)),"")} -> 0 | I25: {=IFERROR(INDEX(Data_CT!M$2:M$327,MATCH($R$2&$R$1&$B25,Data_CT!$B$2:$B$327&Data_CT!$A$2:$A$327&Data_CT!$F$2:$F$327,0)),"")} -> 0 | J25: {=IFERROR(INDEX(Data_CT!N$2:N$327,MATCH($R$2&$R$1&$B25,Data_CT!$B$2:$B$327&Data_CT!$A$2:$A$327&Data_CT!$F$2:$F$327,0)),"")} -> 1.4184815e+08 | K25: {=IFERROR(INDEX(Data_CT!O$2:O$327,MATCH($R$2&$R$1&$B25,Data_CT!$B$2:$B$327&Data_CT!$A$2:$A$327&Data_CT!$F$2:$F$327,0)),"")} -> 141848544 | M25: {=IFERROR(INDEX(Data_CT!P$2:P$327,MATCH($R$2&$R$1&$B25,Data_CT!$B$2:$B$327&Data_CT!$A$2:$A$327&Data_CT!$F$2:$F$327,0)),"")} -> 1195530000 | N25: {=IFERROR(INDEX(Data_CT!Q$2:Q$327,MATCH($R$2&$R$1&$B25,Data_CT!$B$2:$B$327&Data_CT!$A$2:$A$327&Data_CT!$F$2:$F$327,0)),"")} -> 0 | P25: {=IFERROR(INDEX(Data_CT!R$2:R$327,MATCH($R$2&$R$1&$B25,Data_CT!$B$2:$B$327&Data_CT!$A$2:$A$327&Data_CT!$F$2:$F$327,0)),"")} -> 0
A26: 8 | B26: Lô 9B | C26: {=IFERROR(INDEX(Data_CT!G$2:G$327,MATCH($R$2&$R$1&$B26,Data_CT!$B$2:$B$327&Data_CT!$A$2:$A$327&Data_CT!$F$2:$F$327,0)),"")} -> 1487132000 | D26: {=IFERROR(INDEX(Data_CT!H$2:H$327,MATCH($R$2&$R$1&$B26,Data_CT!$B$2:$B$327&Data_CT!$A$2:$A$327&Data_CT!$F$2:$F$327,0)),"")} -> 1487132000 | E26: {=IFERROR(INDEX(Data_CT!I$2:I$327,MATCH($R$2&$R$1&$B26,Data_CT!$B$2:$B$327&Data_CT!$A$2:$A$327&Data_CT!$F$2:$F$327,0)),"")} -> 1150000000 | F26: {=IFERROR(INDEX(Data_CT!J$2:J$327,MATCH($R$2&$R$1&$B26,Data_CT!$B$2:$B$327&Data_CT!$A$2:$A$327&Data_CT!$F$2:$F$327,0)),"")} -> 0 | G26: {=IFERROR(INDEX(Data_CT!K$2:K$327,MATCH($R$2&$R$1&$B26,Data_CT!$B$2:$B$327&Data_CT!$A$2:$A$327&Data_CT!$F$2:$F$327,0)),"")} -> 0 | H26: {=IFERROR(INDEX(Data_CT!L$2:L$327,MATCH($R$2&$R$1&$B26,Data_CT!$B$2:$B$327&Data_CT!$A$2:$A$327&Data_CT!$F$2:$F$327,0)),"")} -> 0 | I26: {=IFERROR(INDEX(Data_CT!M$2:M$327,MATCH($R$2&$R$1&$B26,Data_CT!$B$2:$B$327&Data_CT!$A$2:$A$327&Data_CT!$F$2:$F$327,0)),"")} -> 0 | J26: {=IFERROR(INDEX(Data_CT!N$2:N$327,MATCH($R$2&$R$1&$B26,Data_CT!$B$2:$B$327&Data_CT!$A$2:$A$327&Data_CT!$F$2:$F$327,0)),"")} -> 99454630 | K26: {=IFERROR(INDEX(Data_CT!O$2:O$327,MATCH($R$2&$R$1&$B26,Data_CT!$B$2:$B$327&Data_CT!$A$2:$A$327&Data_CT!$F$2:$F$327,0)),"")} -> 99454630 | M26: {=IFERROR(INDEX(Data_CT!P$2:P$327,MATCH($R$2&$R$1&$B26,Data_CT!$B$2:$B$327&Data_CT!$A$2:$A$327&Data_CT!$F$2:$F$327,0)),"")} | N26: {=IFERROR(INDEX(Data_CT!Q$2:Q$327,MATCH($R$2&$R$1&$B26,Data_CT!$B$2:$B$327&Data_CT!$A$2:$A$327&Data_CT!$F$2:$F$327,0)),"")} -> Xong khung BTCT | P26: {=IFERROR(INDEX(Data_CT!R$2:R$327,MATCH($R$2&$R$1&$B26,Data_CT!$B$2:$B$327&Data_CT!$A$2:$A$327&Data_CT!$F$2:$F$327,0)),"")} -> Xong khung BTCT
A27: 9 | B27: Lô 12B | C27: {=IFERROR(INDEX(Data_CT!G$2:G$327,MATCH($R$2&$R$1&$B27,Data_CT!$B$2:$B$327&Data_CT!$A$2:$A$327&Data_CT!$F$2:$F$327,0)),"")} -> 1590793000 | D27: {=IFERROR(INDEX(Data_CT!H$2:H$327,MATCH($R$2&$R$1&$B27,Data_CT!$B$2:$B$327&Data_CT!$A$2:$A$327&Data_CT!$F$2:$F$327,0)),"")} -> 520020000 | E27: {=IFERROR(INDEX(Data_CT!I$2:I$327,MATCH($R$2&$R$1&$B27,Data_CT!$B$2:$B$327&Data_CT!$A$2:$A$327&Data_CT!$F$2:$F$327,0)),"")} -> 400000000 | F27: {=IFERROR(INDEX(Data_CT!J$2:J$327,MATCH($R$2&$R$1&$B27,Data_CT!$B$2:$B$327&Data_CT!$A$2:$A$327&Data_CT!$F$2:$F$327,0)),"")} -> 0 | G27: {=IFERROR(INDEX(Data_CT!K$2:K$327,MATCH($R$2&$R$1&$B27,Data_CT!$B$2:$B$327&Data_CT!$A$2:$A$327&Data_CT!$F$2:$F$327,0)),"")} -> 0 | H27: {=IFERROR(INDEX(Data_CT!L$2:L$327,MATCH($R$2&$R$1&$B27,Data_CT!$B$2:$B$327&Data_CT!$A$2:$A$327&Data_CT!$F$2:$F$327,0)),"")} -> 0 | I27: {=IFERROR(INDEX(Data_CT!M$2:M$327,MATCH($R$2&$R$1&$B27,Data_CT!$B$2:$B$327&Data_CT!$A$2:$A$327&Data_CT!$F$2:$F$327,0)),"")} -> 0 | J27: {=IFERROR(INDEX(Data_CT!N$2:N$327,MATCH($R$2&$R$1&$B27,Data_CT!$B$2:$B$327&Data_CT!$A$2:$A$327&Data_CT!$F$2:$F$327,0)),"")} -> 0 | K27: {=IFERROR(INDEX(Data_CT!O$2:O$327,MATCH($R$2&$R$1&$B27,Data_CT!$B$2:$B$327&Data_CT!$A$2:$A$327&Data_CT!$F$2:$F$327,0)),"")} -> 0 | M27: {=IFERROR(INDEX(Data_CT!P$2:P$327,MATCH($R$2&$R$1&$B27,Data_CT!$B$2:$B$327&Data_CT!$A$2:$A$327&Data_CT!$F$2:$F$327,0)),"")} | N27: {=IFERROR(INDEX(Data_CT!Q$2:Q$327,MATCH($R$2&$R$1&$B27,Data_CT!$B$2:$B$327&Data_CT!$A$2:$A$327&Data_CT!$F$2:$F$327,0)),"")} -> 0 | P27: {=IFERROR(INDEX(Data_CT!R$2:R$327,MATCH($R$2&$R$1&$B27,Data_CT!$B$2:$B$327&Data_CT!$A$2:$A$327&Data_CT!$F$2:$F$327,0)),"")} -> 0
A28: 10 | B28: Lô 13B-A | C28: {=IFERROR(INDEX(Data_CT!G$2:G$327,MATCH($R$2&$R$1&$B28,Data_CT!$B$2:$B$327&Data_CT!$A$2:$A$327&Data_CT!$F$2:$F$327,0)),"")} -> 1386198000 | D28: {=IFERROR(INDEX(Data_CT!H$2:H$327,MATCH($R$2&$R$1&$B28,Data_CT!$B$2:$B$327&Data_CT!$A$2:$A$327&Data_CT!$F$2:$F$327,0)),"")} -> 220603680 | E28: {=IFERROR(INDEX(Data_CT!I$2:I$327,MATCH($R$2&$R$1&$B28,Data_CT!$B$2:$B$327&Data_CT!$A$2:$A$327&Data_CT!$F$2:$F$327,0)),"")} -> 200000000 | F28: {=IFERROR(INDEX(Data_CT!J$2:J$327,MATCH($R$2&$R$1&$B28,Data_CT!$B$2:$B$327&Data_CT!$A$2:$A$327&Data_CT!$F$2:$F$327,0)),"")} -> 0 | G28: {=IFERROR(INDEX(Data_CT!K$2:K$327,MATCH($R$2&$R$1&$B28,Data_CT!$B$2:$B$327&Data_CT!$A$2:$A$327&Data_CT!$F$2:$F$327,0)),"")} -> 0 | H28: {=IFERROR(INDEX(Data_CT!L$2:L$327,MATCH($R$2&$R$1&$B28,Data_CT!$B$2:$B$327&Data_CT!$A$2:$A$327&Data_CT!$F$2:$F$327,0)),"")} -> 0 | I28: {=IFERROR(INDEX(Data_CT!M$2:M$327,MATCH($R$2&$R$1&$B28,Data_CT!$B$2:$B$327&Data_CT!$A$2:$A$327&Data_CT!$F$2:$F$327,0)),"")} -> 0 | J28: {=IFERROR(INDEX(Data_CT!N$2:N$327,MATCH($R$2&$R$1&$B28,Data_CT!$B$2:$B$327&Data_CT!$A$2:$A$327&Data_CT!$F$2:$F$327,0)),"")} -> 0 | K28: {=IFERROR(INDEX(Data_CT!O$2:O$327,MATCH($R$2&$R$1&$B28,Data_CT!$B$2:$B$327&Data_CT!$A$2:$A$327&Data_CT!$F$2:$F$327,0)),"")} -> 0 | M28: {=IFERROR(INDEX(Data_CT!P$2:P$327,MATCH($R$2&$R$1&$B28,Data_CT!$B$2:$B$327&Data_CT!$A$2:$A$327&Data_CT!$F$2:$F$327,0)),"")} | N28: {=IFERROR(INDEX(Data_CT!Q$2:Q$327,MATCH($R$2&$R$1&$B28,Data_CT!$B$2:$B$327&Data_CT!$A$2:$A$327&Data_CT!$F$2:$F$327,0)),"")} -> Mái tầng 1 | P28: {=IFERROR(INDEX(Data_CT!R$2:R$327,MATCH($R$2&$R$1&$B28,Data_CT!$B$2:$B$327&Data_CT!$A$2:$A$327&Data_CT!$F$2:$F$327,0)),"")} -> Móng
A29: 11 | B29: Lô 13B-B | C29: {=IFERROR(INDEX(Data_CT!G$2:G$327,MATCH($R$2&$R$1&$B29,Data_CT!$B$2:$B$327&Data_CT!$A$2:$A$327&Data_CT!$F$2:$F$327,0)),"")} -> 1151187000 | D29: {=IFERROR(INDEX(Data_CT!H$2:H$327,MATCH($R$2&$R$1&$B29,Data_CT!$B$2:$B$327&Data_CT!$A$2:$A$327&Data_CT!$F$2:$F$327,0)),"")} -> 1151187000 | E29: {=IFERROR(INDEX(Data_CT!I$2:I$327,MATCH($R$2&$R$1&$B29,Data_CT!$B$2:$B$327&Data_CT!$A$2:$A$327&Data_CT!$F$2:$F$327,0)),"")} -> 1151187000 | F29: {=IFERROR(INDEX(Data_CT!J$2:J$327,MATCH($R$2&$R$1&$B29,Data_CT!$B$2:$B$327&Data_CT!$A$2:$A$327&Data_CT!$F$2:$F$327,0)),"")} -> 0 | G29: {=IFERROR(INDEX(Data_CT!K$2:K$327,MATCH($R$2&$R$1&$B29,Data_CT!$B$2:$B$327&Data_CT!$A$2:$A$327&Data_CT!$F$2:$F$327,0)),"")} -> 0 | H29: {=IFERROR(INDEX(Data_CT!L$2:L$327,MATCH($R$2&$R$1&$B29,Data_CT!$B$2:$B$327&Data_CT!$A$2:$A$327&Data_CT!$F$2:$F$327,0)),"")} -> 0 | I29: {=IFERROR(INDEX(Data_CT!M$2:M$327,MATCH($R$2&$R$1&$B29,Data_CT!$B$2:$B$327&Data_CT!$A$2:$A$327&Data_CT!$F$2:$F$327,0)),"")} -> 0 | J29: {=IFERROR(INDEX(Data_CT!N$2:N$327,MATCH($R$2&$R$1&$B29,Data_CT!$B$2:$B$327&Data_CT!$A$2:$A$327&Data_CT!$F$2:$F$327,0)),"")} -> 139475000 | K29: {=IFERROR(INDEX(Data_CT!O$2:O$327,MATCH($R$2&$R$1&$B29,Data_CT!$B$2:$B$327&Data_CT!$A$2:$A$327&Data_CT!$F$2:$F$327,0)),"")} -> 139474971 | M29: {=IFERROR(INDEX(Data_CT!P$2:P$327,MATCH($R$2&$R$1&$B29,Data_CT!$B$2:$B$327&Data_CT!$A$2:$A$327&Data_CT!$F$2:$F$327,0)),"")} -> 1151187000 | N29: {=IFERROR(INDEX(Data_CT!Q$2:Q$327,MATCH($R$2&$R$1&$B29,Data_CT!$B$2:$B$327&Data_CT!$A$2:$A$327&Data_CT!$F$2:$F$327,0)),"")} -> 0 | P29: {=IFERROR(INDEX(Data_CT!R$2:R$327,MATCH($R$2&$R$1&$B29,Data_CT!$B$2:$B$327&Data_CT!$A$2:$A$327&Data_CT!$F$2:$F$327,0)),"")} -> 0
A30: 12 | B30: Lô 14B | C30: {=IFERROR(INDEX(Data_CT!G$2:G$327,MATCH($R$2&$R$1&$B30,Data_CT!$B$2:$B$327&Data_CT!$A$2:$A$327&Data_CT!$F$2:$F$327,0)),"")} -> 1599758000 | D30: {=IFERROR(INDEX(Data_CT!H$2:H$327,MATCH($R$2&$R$1&$B30,Data_CT!$B$2:$B$327&Data_CT!$A$2:$A$327&Data_CT!$F$2:$F$327,0)),"")} -> 1599758000 | E30: {=IFERROR(INDEX(Data_CT!I$2:I$327,MATCH($R$2&$R$1&$B30,Data_CT!$B$2:$B$327&Data_CT!$A$2:$A$327&Data_CT!$F$2:$F$327,0)),"")} -> 1599758000 | F30: {=IFERROR(INDEX(Data_CT!J$2:J$327,MATCH($R$2&$R$1&$B30,Data_CT!$B$2:$B$327&Data_CT!$A$2:$A$327&Data_CT!$F$2:$F$327,0)),"")} -> 0 | G30: {=IFERROR(INDEX(Data_CT!K$2:K$327,MATCH($R$2&$R$1&$B30,Data_CT!$B$2:$B$327&Data_CT!$A$2:$A$327&Data_CT!$F$2:$F$327,0)),"")} -> 0 | H30: {=IFERROR(INDEX(Data_CT!L$2:L$327,MATCH($R$2&$R$1&$B30,Data_CT!$B$2:$B$327&Data_CT!$A$2:$A$327&Data_CT!$F$2:$F$327,0)),"")} -> 0 | I30: {=IFERROR(INDEX(Data_CT!M$2:M$327,MATCH($R$2&$R$1&$B30,Data_CT!$B$2:$B$327&Data_CT!$A$2:$A$327&Data_CT!$F$2:$F$327,0)),"")} -> 0 | J30: {=IFERROR(INDEX(Data_CT!N$2:N$327,MATCH($R$2&$R$1&$B30,Data_CT!$B$2:$B$327&Data_CT!$A$2:$A$327&Data_CT!$F$2:$F$327,0)),"")} -> 0 | K30: {=IFERROR(INDEX(Data_CT!O$2:O$327,MATCH($R$2&$R$1&$B30,Data_CT!$B$2:$B$327&Data_CT!$A$2:$A$327&Data_CT!$F$2:$F$327,0)),"")} -> 135344191 | M30: {=IFERROR(INDEX(Data_CT!P$2:P$327,MATCH($R$2&$R$1&$B30,Data_CT!$B$2:$B$327&Data_CT!$A$2:$A$327&Data_CT!$F$2:$F$327,0)),"")} -> 1599758000 | N30: {=IFERROR(INDEX(Data_CT!Q$2:Q$327,MATCH($R$2&$R$1&$B30,Data_CT!$B$2:$B$327&Data_CT!$A$2:$A$327&Data_CT!$F$2:$F$327,0)),"")} -> Xong khung BTCT | P30: {=IFERROR(INDEX(Data_CT!R$2:R$327,MATCH($R$2&$R$1&$B30,Data_CT!$B$2:$B$327&Data_CT!$A$2:$A$327&Data_CT!$F$2:$F$327,0)),"")} -> Xong khung BTCT
A31: 13 | B31: Lô 15B | C31: {=IFERROR(INDEX(Data_CT!G$2:G$327,MATCH($R$2&$R$1&$B31,Data_CT!$B$2:$B$327&Data_CT!$A$2:$A$327&Data_CT!$F$2:$F$327,0)),"")} -> 1512938000 | D31: {=IFERROR(INDEX(Data_CT!H$2:H$327,MATCH($R$2&$R$1&$B31,Data_CT!$B$2:$B$327&Data_CT!$A$2:$A$327&Data_CT!$F$2:$F$327,0)),"")} -> 1512938000 | E31: {=IFERROR(INDEX(Data_CT!I$2:I$327,MATCH($R$2&$R$1&$B31,Data_CT!$B$2:$B$327&Data_CT!$A$2:$A$327&Data_CT!$F$2:$F$327,0)),"")} -> 1512938000 | F31: {=IFERROR(INDEX(Data_CT!J$2:J$327,MATCH($R$2&$R$1&$B31,Data_CT!$B$2:$B$327&Data_CT!$A$2:$A$327&Data_CT!$F$2:$F$327,0)),"")} -> 0 | G31: {=IFERROR(INDEX(Data_CT!K$2:K$327,MATCH($R$2&$R$1&$B31,Data_CT!$B$2:$B$327&Data_CT!$A$2:$A$327&Data_CT!$F$2:$F$327,0)),"")} -> 0 | H31: {=IFERROR(INDEX(Data_CT!L$2:L$327,MATCH($R$2&$R$1&$B31,Data_CT!$B$2:$B$327&Data_CT!$A$2:$A$327&Data_CT!$F$2:$F$327,0)),"")} -> 0 | I31: {=IFERROR(INDEX(Data_CT!M$2:M$327,MATCH($R$2&$R$1&$B31,Data_CT!$B$2:$B$327&Data_CT!$A$2:$A$327&Data_CT!$F$2:$F$327,0)),"")} -> 0 | J31: {=IFERROR(INDEX(Data_CT!N$2:N$327,MATCH($R$2&$R$1&$B31,Data_CT!$B$2:$B$327&Data_CT!$A$2:$A$327&Data_CT!$F$2:$F$327,0)),"")} -> 1.4588333e+08 | K31: {=IFERROR(INDEX(Data_CT!O$2:O$327,MATCH($R$2&$R$1&$B31,Data_CT!$B$2:$B$327&Data_CT!$A$2:$A$327&Data_CT!$F$2:$F$327,0)),"")} -> 145883155 | M31: {=IFERROR(INDEX(Data_CT!P$2:P$327,MATCH($R$2&$R$1&$B31,Data_CT!$B$2:$B$327&Data_CT!$A$2:$A$327&Data_CT!$F$2:$F$327,0)),"")} -> 1512938000 | N31: {=IFERROR(INDEX(Data_CT!Q$2:Q$327,MATCH($R$2&$R$1&$B31,Data_CT!$B$2:$B$327&Data_CT!$A$2:$A$327&Data_CT!$F$2:$F$327,0)),"")} -> 0 | P31: {=IFERROR(INDEX(Data_CT!R$2:R$327,MATCH($R$2&$R$1&$B31,Data_CT!$B$2:$B$327&Data_CT!$A$2:$A$327&Data_CT!$F$2:$F$327,0)),"")} -> 0
A32: 14 | B32: Lô 16B | C32: {=IFERROR(INDEX(Data_CT!G$2:G$327,MATCH($R$2&$R$1&$B32,Data_CT!$B$2:$B$327&Data_CT!$A$2:$A$327&Data_CT!$F$2:$F$327,0)),"")} -> 1593398000 | D32: {=IFERROR(INDEX(Data_CT!H$2:H$327,MATCH($R$2&$R$1&$B32,Data_CT!$B$2:$B$327&Data_CT!$A$2:$A$327&Data_CT!$F$2:$F$327,0)),"")} -> 1593398000 | E32: {=IFERROR(INDEX(Data_CT!I$2:I$327,MATCH($R$2&$R$1&$B32,Data_CT!$B$2:$B$327&Data_CT!$A$2:$A$327&Data_CT!$F$2:$F$327,0)),"")} -> 1593398000 | F32: {=IFERROR(INDEX(Data_CT!J$2:J$327,MATCH($R$2&$R$1&$B32,Data_CT!$B$2:$B$327&Data_CT!$A$2:$A$327&Data_CT!$F$2:$F$327,0)),"")} -> 0 | G32: {=IFERROR(INDEX(Data_CT!K$2:K$327,MATCH($R$2&$R$1&$B32,Data_CT!$B$2:$B$327&Data_CT!$A$2:$A$327&Data_CT!$F$2:$F$327,0)),"")} -> 0 | H32: {=IFERROR(INDEX(Data_CT!L$2:L$327,MATCH($R$2&$R$1&$B32,Data_CT!$B$2:$B$327&Data_CT!$A$2:$A$327&Data_CT!$F$2:$F$327,0)),"")} -> 0 | I32: {=IFERROR(INDEX(Data_CT!M$2:M$327,MATCH($R$2&$R$1&$B32,Data_CT!$B$2:$B$327&Data_CT!$A$2:$A$327&Data_CT!$F$2:$F$327,0)),"")} -> 0 | J32: {=IFERROR(INDEX(Data_CT!N$2:N$327,MATCH($R$2&$R$1&$B32,Data_CT!$B$2:$B$327&Data_CT!$A$2:$A$327&Data_CT!$F$2:$F$327,0)),"")} -> 113004630 | K32: {=IFERROR(INDEX(Data_CT!O$2:O$327,MATCH($R$2&$R$1&$B32,Data_CT!$B$2:$B$327&Data_CT!$A$2:$A$327&Data_CT!$F$2:$F$327,0)),"")} -> 113004411 | M32: {=IFERROR(INDEX(Data_CT!P$2:P$327,MATCH($R$2&$R$1&$B32,Data_CT!$B$2:$B$327&Data_CT!$A$2:$A$327&Data_CT!$F$2:$F$327,0)),"")} -> 1593398000 | N32: {=IFERROR(INDEX(Data_CT!Q$2:Q$327,MATCH($R$2&$R$1&$B32,Data_CT!$B$2:$B$327&Data_CT!$A$2:$A$327&Data_CT!$F$2:$F$327,0)),"")} -> 0 | P32: {=IFERROR(INDEX(Data_CT!R$2:R$327,MATCH($R$2&$R$1&$B32,Data_CT!$B$2:$B$327&Data_CT!$A$2:$A$327&Data_CT!$F$2:$F$327,0)),"")} -> 0
A33: 15 | B33: Lô 17B | C33: {=IFERROR(INDEX(Data_CT!G$2:G$327,MATCH($R$2&$R$1&$B33,Data_CT!$B$2:$B$327&Data_CT!$A$2:$A$327&Data_CT!$F$2:$F$327,0)),"")} -> 1168758000 | D33: {=IFERROR(INDEX(Data_CT!H$2:H$327,MATCH($R$2&$R$1&$B33,Data_CT!$B$2:$B$327&Data_CT!$A$2:$A$327&Data_CT!$F$2:$F$327,0)),"")} -> 1168758000 | E33: {=IFERROR(INDEX(Data_CT!I$2:I$327,MATCH($R$2&$R$1&$B33,Data_CT!$B$2:$B$327&Data_CT!$A$2:$A$327&Data_CT!$F$2:$F$327,0)),"")} -> 300000000 | F33: {=IFERROR(INDEX(Data_CT!J$2:J$327,MATCH($R$2&$R$1&$B33,Data_CT!$B$2:$B$327&Data_CT!$A$2:$A$327&Data_CT!$F$2:$F$327,0)),"")} -> 0 | G33: {=IFERROR(INDEX(Data_CT!K$2:K$327,MATCH($R$2&$R$1&$B33,Data_CT!$B$2:$B$327&Data_CT!$A$2:$A$327&Data_CT!$F$2:$F$327,0)),"")} -> 0 | H33: {=IFERROR(INDEX(Data_CT!L$2:L$327,MATCH($R$2&$R$1&$B33,Data_CT!$B$2:$B$327&Data_CT!$A$2:$A$327&Data_CT!$F$2:$F$327,0)),"")} -> 0 | I33: {=IFERROR(INDEX(Data_CT!M$2:M$327,MATCH($R$2&$R$1&$B33,Data_CT!$B$2:$B$327&Data_CT!$A$2:$A$327&Data_CT!$F$2:$F$327,0)),"")} -> 0 | J33: {=IFERROR(INDEX(Data_CT!N$2:N$327,MATCH($R$2&$R$1&$B33,Data_CT!$B$2:$B$327&Data_CT!$A$2:$A$327&Data_CT!$F$2:$F$327,0)),"")} -> 0 | K33: {=IFERROR(INDEX(Data_CT!O$2:O$327,MATCH($R$2&$R$1&$B33,Data_CT!$B$2:$B$327&Data_CT!$A$2:$A$327&Data_CT!$F$2:$F$327,0)),"")} -> 0 | M33: {=IFERROR(INDEX(Data_CT!P$2:P$327,MATCH($R$2&$R$1&$B33,Data_CT!$B$2:$B$327&Data_CT!$A$2:$A$327&Data_CT!$F$2:$F$327,0)),"")} | N33: {=IFERROR(INDEX(Data_CT!Q$2:Q$327,MATCH($R$2&$R$1&$B33,Data_CT!$B$2:$B$327&Data_CT!$A$2:$A$327&Data_CT!$F$2:$F$327,0)),"")} -> 0 | P33: {=IFERROR(INDEX(Data_CT!R$2:R$327,MATCH($R$2&$R$1&$B33,Data_CT!$B$2:$B$327&Data_CT!$A$2:$A$327&Data_CT!$F$2:$F$327,0)),"")} -> Xong khung BTCT
A34: C | D34: 0 | E34: 0
A35: 1 | B35: Lô 1C | C35: {=IFERROR(INDEX(Data_CT!G$2:G$327,MATCH($R$2&$R$1&$B35,Data_CT!$B$2:$B$327&Data_CT!$A$2:$A$327&Data_CT!$F$2:$F$327,0)),"")} -> 1566568000 | D35: {=IFERROR(INDEX(Data_CT!H$2:H$327,MATCH($R$2&$R$1&$B35,Data_CT!$B$2:$B$327&Data_CT!$A$2:$A$327&Data_CT!$F$2:$F$327,0)),"")} -> 1566568000 | E35: {=IFERROR(INDEX(Data_CT!I$2:I$327,MATCH($R$2&$R$1&$B35,Data_CT!$B$2:$B$327&Data_CT!$A$2:$A$327&Data_CT!$F$2:$F$327,0)),"")} -> 1566568000 | F35: {=IFERROR(INDEX(Data_CT!J$2:J$327,MATCH($R$2&$R$1&$B35,Data_CT!$B$2:$B$327&Data_CT!$A$2:$A$327&Data_CT!$F$2:$F$327,0)),"")} -> 0 | G35: {=IFERROR(INDEX(Data_CT!K$2:K$327,MATCH($R$2&$R$1&$B35,Data_CT!$B$2:$B$327&Data_CT!$A$2:$A$327&Data_CT!$F$2:$F$327,0)),"")} -> 0 | H35: {=IFERROR(INDEX(Data_CT!L$2:L$327,MATCH($R$2&$R$1&$B35,Data_CT!$B$2:$B$327&Data_CT!$A$2:$A$327&Data_CT!$F$2:$F$327,0)),"")} -> 0 | I35: {=IFERROR(INDEX(Data_CT!M$2:M$327,MATCH($R$2&$R$1&$B35,Data_CT!$B$2:$B$327&Data_CT!$A$2:$A$327&Data_CT!$F$2:$F$327,0)),"")} -> 0 | J35: {=IFERROR(INDEX(Data_CT!N$2:N$327,MATCH($R$2&$R$1&$B35,Data_CT!$B$2:$B$327&Data_CT!$A$2:$A$327&Data_CT!$F$2:$F$327,0)),"")} -> 2.039287e+08 | K35: {=IFERROR(INDEX(Data_CT!O$2:O$327,MATCH($R$2&$R$1&$B35,Data_CT!$B$2:$B$327&Data_CT!$A$2:$A$327&Data_CT!$F$2:$F$327,0)),"")} -> 203928704 | M35: {=IFERROR(INDEX(Data_CT!P$2:P$327,MATCH($R$2&$R$1&$B35,Data_CT!$B$2:$B$327&Data_CT!$A$2:$A$327&Data_CT!$F$2:$F$327,0)),"")} -> 1566568000 | N35: {=IFERROR(INDEX(Data_CT!Q$2:Q$327,MATCH($R$2&$R$1&$B35,Data_CT!$B$2:$B$327&Data_CT!$A$2:$A$327&Data_CT!$F$2:$F$327,0)),"")} -> 0 | P35: {=IFERROR(INDEX(Data_CT!R$2:R$327,MATCH($R$2&$R$1&$B35,Data_CT!$B$2:$B$327&Data_CT!$A$2:$A$327&Data_CT!$F$2:$F$327,0)),"")} -> 0
A36: 2 | B36: Lô 2C | C36: {=IFERROR(INDEX(Data_CT!G$2:G$327,MATCH($R$2&$R$1&$B36,Data_CT!$B$2:$B$327&Data_CT!$A$2:$A$327&Data_CT!$F$2:$F$327,0)),"")} -> 1264042000 | D36: {=IFERROR(INDEX(Data_CT!H$2:H$327,MATCH($R$2&$R$1&$B36,Data_CT!$B$2:$B$327&Data_CT!$A$2:$A$327&Data_CT!$F$2:$F$327,0)),"")} -> 620557920 | E36: {=IFERROR(INDEX(Data_CT!I$2:I$327,MATCH($R$2&$R$1&$B36,Data_CT!$B$2:$B$327&Data_CT!$A$2:$A$327&Data_CT!$F$2:$F$327,0)),"")} -> 800000000 | F36: {=IFERROR(INDEX(Data_CT!J$2:J$327,MATCH($R$2&$R$1&$B36,Data_CT!$B$2:$B$327&Data_CT!$A$2:$A$327&Data_CT!$F$2:$F$327,0)),"")} -> 0 | G36: {=IFERROR(INDEX(Data_CT!K$2:K$327,MATCH($R$2&$R$1&$B36,Data_CT!$B$2:$B$327&Data_CT!$A$2:$A$327&Data_CT!$F$2:$F$327,0)),"")} -> 174384000 | H36: {=IFERROR(INDEX(Data_CT!L$2:L$327,MATCH($R$2&$R$1&$B36,Data_CT!$B$2:$B$327&Data_CT!$A$2:$A$327&Data_CT!$F$2:$F$327,0)),"")} -> 0 | I36: {=IFERROR(INDEX(Data_CT!M$2:M$327,MATCH($R$2&$R$1&$B36,Data_CT!$B$2:$B$327&Data_CT!$A$2:$A$327&Data_CT!$F$2:$F$327,0)),"")} -> 0 | J36: {=IFERROR(INDEX(Data_CT!N$2:N$327,MATCH($R$2&$R$1&$B36,Data_CT!$B$2:$B$327&Data_CT!$A$2:$A$327&Data_CT!$F$2:$F$327,0)),"")} -> 0 | K36: {=IFERROR(INDEX(Data_CT!O$2:O$327,MATCH($R$2&$R$1&$B36,Data_CT!$B$2:$B$327&Data_CT!$A$2:$A$327&Data_CT!$F$2:$F$327,0)),"")} -> 0 | M36: {=IFERROR(INDEX(Data_CT!P$2:P$327,MATCH($R$2&$R$1&$B36,Data_CT!$B$2:$B$327&Data_CT!$A$2:$A$327&Data_CT!$F$2:$F$327,0)),"")} | N36: {=IFERROR(INDEX(Data_CT!Q$2:Q$327,MATCH($R$2&$R$1&$B36,Data_CT!$B$2:$B$327&Data_CT!$A$2:$A$327&Data_CT!$F$2:$F$327,0)),"")} -> Mái tầng 1 | P36: {=IFERROR(INDEX(Data_CT!R$2:R$327,MATCH($R$2&$R$1&$B36,Data_CT!$B$2:$B$327&Data_CT!$A$2:$A$327&Data_CT!$F$2:$F$327,0)),"")} -> Xong khung BTCT
A37: 3 | B37: Lô 3C | C37: {=IFERROR(INDEX(Data_CT!G$2:G$327,MATCH($R$2&$R$1&$B37,Data_CT!$B$2:$B$327&Data_CT!$A$2:$A$327&Data_CT!$F$2:$F$327,0)),"")} -> 1264264000 | D37: {=IFERROR(INDEX(Data_CT!H$2:H$327,MATCH($R$2&$R$1&$B37,Data_CT!$B$2:$B$327&Data_CT!$A$2:$A$327&Data_CT!$F$2:$F$327,0)),"")} -> 792201600 | E37: {=IFERROR(INDEX(Data_CT!I$2:I$327,MATCH($R$2&$R$1&$B37,Data_CT!$B$2:$B$327&Data_CT!$A$2:$A$327&Data_CT!$F$2:$F$327,0)),"")} -> 400000000 | F37: {=IFERROR(INDEX(Data_CT!J$2:J$327,MATCH($R$2&$R$1&$B37,Data_CT!$B$2:$B$327&Data_CT!$A$2:$A$327&Data_CT!$F$2:$F$327,0)),"")} -> 0 | G37: {=IFERROR(INDEX(Data_CT!K$2:K$327,MATCH($R$2&$R$1&$B37,Data_CT!$B$2:$B$327&Data_CT!$A$2:$A$327&Data_CT!$F$2:$F$327,0)),"")} -> 336312000 | H37: {=IFERROR(INDEX(Data_CT!L$2:L$327,MATCH($R$2&$R$1&$B37,Data_CT!$B$2:$B$327&Data_CT!$A$2:$A$327&Data_CT!$F$2:$F$327,0)),"")} -> 400000000 | I37: {=IFERROR(INDEX(Data_CT!M$2:M$327,MATCH($R$2&$R$1&$B37,Data_CT!$B$2:$B$327&Data_CT!$A$2:$A$327&Data_CT!$F$2:$F$327,0)),"")} -> 0 | J37: {=IFERROR(INDEX(Data_CT!N$2:N$327,MATCH($R$2&$R$1&$B37,Data_CT!$B$2:$B$327&Data_CT!$A$2:$A$327&Data_CT!$F$2:$F$327,0)),"")} -> 0 | K37: {=IFERROR(INDEX(Data_CT!O$2:O$327,MATCH($R$2&$R$1&$B37,Data_CT!$B$2:$B$327&Data_CT!$A$2:$A$327&Data_CT!$F$2:$F$327,0)),"")} -> 0 | M37: {=IFERROR(INDEX(Data_CT!P$2:P$327,MATCH($R$2&$R$1&$B37,Data_CT!$B$2:$B$327&Data_CT!$A$2:$A$327&Data_CT!$F$2:$F$327,0)),"")} | N37: {=IFERROR(INDEX(Data_CT!Q$2:Q$327,MATCH($R$2&$R$1&$B37,Data_CT!$B$2:$B$327&Data_CT!$A$2:$A$327&Data_CT!$F$2:$F$327,0)),"")} -> Mái tầng 1 | P37: {=IFERROR(INDEX(Data_CT!R$2:R$327,MATCH($R$2&$R$1&$B37,Data_CT!$B$2:$B$327&Data_CT!$A$2:$A$327&Data_CT!$F$2:$F$327,0)),"")} -> Xong khung BTCT
A38: 4 | B38: Lô 4C | C38: {=IFERROR(INDEX(Data_CT!G$2:G$327,MATCH($R$2&$R$1&$B38,Data_CT!$B$2:$B$327&Data_CT!$A$2:$A$327&Data_CT!$F$2:$F$327,0)),"")} -> 929889000 | D38: {=IFERROR(INDEX(Data_CT!H$2:H$327,MATCH($R$2&$R$1&$B38,Data_CT!$B$2:$B$327&Data_CT!$A$2:$A$327&Data_CT!$F$2:$F$327,0)),"")} -> 929889000 | E38: {=IFERROR(INDEX(Data_CT!I$2:I$327,MATCH($R$2&$R$1&$B38,Data_CT!$B$2:$B$327&Data_CT!$A$2:$A$327&Data_CT!$F$2:$F$327,0)),"")} -> 929889000 | F38: {=IFERROR(INDEX(Data_CT!J$2:J$327,MATCH($R$2&$R$1&$B38,Data_CT!$B$2:$B$327&Data_CT!$A$2:$A$327&Data_CT!$F$2:$F$327,0)),"")} -> 0 | G38: {=IFERROR(INDEX(Data_CT!K$2:K$327,MATCH($R$2&$R$1&$B38,Data_CT!$B$2:$B$327&Data_CT!$A$2:$A$327&Data_CT!$F$2:$F$327,0)),"")} -> 0 | H38: {=IFERROR(INDEX(Data_CT!L$2:L$327,MATCH($R$2&$R$1&$B38,Data_CT!$B$2:$B$327&Data_CT!$A$2:$A$327&Data_CT!$F$2:$F$327,0)),"")} -> 0 | I38: {=IFERROR(INDEX(Data_CT!M$2:M$327,MATCH($R$2&$R$1&$B38,Data_CT!$B$2:$B$327&Data_CT!$A$2:$A$327&Data_CT!$F$2:$F$327,0)),"")} -> 0 | J38: {=IFERROR(INDEX(Data_CT!N$2:N$327,MATCH($R$2&$R$1&$B38,Data_CT!$B$2:$B$327&Data_CT!$A$2:$A$327&Data_CT!$F$2:$F$327,0)),"")} -> 41061111 | K38: {=IFERROR(INDEX(Data_CT!O$2:O$327,MATCH($R$2&$R$1&$B38,Data_CT!$B$2:$B$327&Data_CT!$A$2:$A$327&Data_CT!$F$2:$F$327,0)),"")} -> 41060664 | M38: {=IFERROR(INDEX(Data_CT!P$2:P$327,MATCH($R$2&$R$1&$B38,Data_CT!$B$2:$B$327&Data_CT!$A$2:$A$327&Data_CT!$F$2:$F$327,0)),"")} | N38: {=IFERROR(INDEX(Data_CT!Q$2:Q$327,MATCH($R$2&$R$1&$B38,Data_CT!$B$2:$B$327&Data_CT!$A$2:$A$327&Data_CT!$F$2:$F$327,0)),"")} -> Xong khung BTCT | P38: {=IFERROR(INDEX(Data_CT!R$2:R$327,MATCH($R$2&$R$1&$B38,Data_CT!$B$2:$B$327&Data_CT!$A$2:$A$327&Data_CT!$F$2:$F$327,0)),"")} -> Xong khung BTCT
A39: 5 | B39: Lô 7C | C39: {=IFERROR(INDEX(Data_CT!G$2:G$327,MATCH($R$2&$R$1&$B39,Data_CT!$B$2:$B$327&Data_CT!$A$2:$A$327&Data_CT!$F$2:$F$327,0)),"")} -> 1150397000 | D39: {=IFERROR(INDEX(Data_CT!H$2:H$327,MATCH($R$2&$R$1&$B39,Data_CT!$B$2:$B$327&Data_CT!$A$2:$A$327&Data_CT!$F$2:$F$327,0)),"")} -> 1150397000 | E39: {=IFERROR(INDEX(Data_CT!I$2:I$327,MATCH($R$2&$R$1&$B39,Data_CT!$B$2:$B$327&Data_CT!$A$2:$A$327&Data_CT!$F$2:$F$327,0)),"")} -> 1150397000 | F39: {=IFERROR(INDEX(Data_CT!J$2:J$327,MATCH($R$2&$R$1&$B39,Data_CT!$B$2:$B$327&Data_CT!$A$2:$A$327&Data_CT!$F$2:$F$327,0)),"")} -> 0 | G39: {=IFERROR(INDEX(Data_CT!K$2:K$327,MATCH($R$2&$R$1&$B39,Data_CT!$B$2:$B$327&Data_CT!$A$2:$A$327&Data_CT!$F$2:$F$327,0)),"")} -> 0 | H39: {=IFERROR(INDEX(Data_CT!L$2:L$327,MATCH($R$2&$R$1&$B39,Data_CT!$B$2:$B$327&Data_CT!$A$2:$A$327&Data_CT!$F$2:$F$327,0)),"")} -> 0 | I39: {=IFERROR(INDEX(Data_CT!M$2:M$327,MATCH($R$2&$R$1&$B39,Data_CT!$B$2:$B$327&Data_CT!$A$2:$A$327&Data_CT!$F$2:$F$327,0)),"")} -> 0 | J39: {=IFERROR(INDEX(Data_CT!N$2:N$327,MATCH($R$2&$R$1&$B39,Data_CT!$B$2:$B$327&Data_CT!$A$2:$A$327&Data_CT!$F$2:$F$327,0)),"")} -> 157625000 | K39: {=IFERROR(INDEX(Data_CT!O$2:O$327,MATCH($R$2&$R$1&$B39,Data_CT!$B$2:$B$327&Data_CT!$A$2:$A$327&Data_CT!$F$2:$F$327,0)),"")} -> 157624826 | M39: {=IFERROR(INDEX(Data_CT!P$2:P$327,MATCH($R$2&$R$1&$B39,Data_CT!$B$2:$B$327&Data_CT!$A$2:$A$327&Data_CT!$F$2:$F$327,0)),"")} -> 1150397000 | N39: {=IFERROR(INDEX(Data_CT!Q$2:Q$327,MATCH($R$2&$R$1&$B39,Data_CT!$B$2:$B$327&Data_CT!$A$2:$A$327&Data_CT!$F$2:$F$327,0)),"")} -> 0 | P39: {=IFERROR(INDEX(Data_CT!R$2:R$327,MATCH($R$2&$R$1&$B39,Data_CT!$B$2:$B$327&Data_CT!$A$2:$A$327&Data_CT!$F$2:$F$327,0)),"")} -> 0
A40: 6 | B40: Lô 9C | C40: {=IFERROR(INDEX(Data_CT!G$2:G$327,MATCH($R$2&$R$1&$B40,Data_CT!$B$2:$B$327&Data_CT!$A$2:$A$327&Data_CT!$F$2:$F$327,0)),"")} -> 1688339000 | D40: {=IFERROR(INDEX(Data_CT!H$2:H$327,MATCH($R$2&$R$1&$B40,Data_CT!$B$2:$B$327&Data_CT!$A$2:$A$327&Data_CT!$F$2:$F$327,0)),"")} -> 150943500 | E40: {=IFERROR(INDEX(Data_CT!I$2:I$327,MATCH($R$2&$R$1&$B40,Data_CT!$B$2:$B$327&Data_CT!$A$2:$A$327&Data_CT!$F$2:$F$327,0)),"")} -> 300000000 | F40: {=IFERROR(INDEX(Data_CT!J$2:J$327,MATCH($R$2&$R$1&$B40,Data_CT!$B$2:$B$327&Data_CT!$A$2:$A$327&Data_CT!$F$2:$F$327,0)),"")} -> 0 | G40: {=IFERROR(INDEX(Data_CT!K$2:K$327,MATCH($R$2&$R$1&$B40,Data_CT!$B$2:$B$327&Data_CT!$A$2:$A$327&Data_CT!$F$2:$F$327,0)),"")} -> 184486500 | H40: {=IFERROR(INDEX(Data_CT!L$2:L$327,MATCH($R$2&$R$1&$B40,Data_CT!$B$2:$B$327&Data_CT!$A$2:$A$327&Data_CT!$F$2:$F$327,0)),"")} -> 200000000 | I40: {=IFERROR(INDEX(Data_CT!M$2:M$327,MATCH($R$2&$R$1&$B40,Data_CT!$B$2:$B$327&Data_CT!$A$2:$A$327&Data_CT!$F$2:$F$327,0)),"")} -> 0 | J40: {=IFERROR(INDEX(Data_CT!N$2:N$327,MATCH($R$2&$R$1&$B40,Data_CT!$B$2:$B$327&Data_CT!$A$2:$A$327&Data_CT!$F$2:$F$327,0)),"")} -> 0 | K40: {=IFERROR(INDEX(Data_CT!O$2:O$327,MATCH($R$2&$R$1&$B40,Data_CT!$B$2:$B$327&Data_CT!$A$2:$A$327&Data_CT!$F$2:$F$327,0)),"")} -> 0 | M40: {=IFERROR(INDEX(Data_CT!P$2:P$327,MATCH($R$2&$R$1&$B40,Data_CT!$B$2:$B$327&Data_CT!$A$2:$A$327&Data_CT!$F$2:$F$327,0)),"")} | N40: {=IFERROR(INDEX(Data_CT!Q$2:Q$327,MATCH($R$2&$R$1&$B40,Data_CT!$B$2:$B$327&Data_CT!$A$2:$A$327&Data_CT!$F$2:$F$327,0)),"")} -> 0 | P40: {=IFERROR(INDEX(Data_CT!R$2:R$327,MATCH($R$2&$R$1&$B40,Data_CT!$B$2:$B$327&Data_CT!$A$2:$A$327&Data_CT!$F$2:$F$327,0)),"")} -> Móng
A41: 7 | B41: Lô 11C | C41: {=IFERROR(INDEX(Data_CT!G$2:G$327,MATCH($R$2&$R$1&$B41,Data_CT!$B$2:$B$327&Data_CT!$A$2:$A$327&Data_CT!$F$2:$F$327,0)),"")} -> 1437536000 | D41: {=IFERROR(INDEX(Data_CT!H$2:H$327,MATCH($R$2&$R$1&$B41,Data_CT!$B$2:$B$327&Data_CT!$A$2:$A$327&Data_CT!$F$2:$F$327,0)),"")} -> 117612000 | E41: {=IFERROR(INDEX(Data_CT!I$2:I$327,MATCH($R$2&$R$1&$B41,Data_CT!$B$2:$B$327&Data_CT!$A$2:$A$327&Data_CT!$F$2:$F$327,0)),"")} -> 450000000 | F41: {=IFERROR(INDEX(Data_CT!J$2:J$327,MATCH($R$2&$R$1&$B41,Data_CT!$B$2:$B$327&Data_CT!$A$2:$A$327&Data_CT!$F$2:$F$327,0)),"")} -> 0 | G41: {=IFERROR(INDEX(Data_CT!K$2:K$327,MATCH($R$2&$R$1&$B41,Data_CT!$B$2:$B$327&Data_CT!$A$2:$A$327&Data_CT!$F$2:$F$327,0)),"")} -> 313632000 | H41: {=IFERROR(INDEX(Data_CT!L$2:L$327,MATCH($R$2&$R$1&$B41,Data_CT!$B$2:$B$327&Data_CT!$A$2:$A$327&Data_CT!$F$2:$F$327,0)),"")} -> 0 | I41: {=IFERROR(INDEX(Data_CT!M$2:M$327,MATCH($R$2&$R$1&$B41,Data_CT!$B$2:$B$327&Data_CT!$A$2:$A$327&Data_CT!$F$2:$F$327,0)),"")} -> 0 | J41: {=IFERROR(INDEX(Data_CT!N$2:N$327,MATCH($R$2&$R$1&$B41,Data_CT!$B$2:$B$327&Data_CT!$A$2:$A$327&Data_CT!$F$2:$F$327,0)),"")} -> 0 | K41: {=IFERROR(INDEX(Data_CT!O$2:O$327,MATCH($R$2&$R$1&$B41,Data_CT!$B$2:$B$327&Data_CT!$A$2:$A$327&Data_CT!$F$2:$F$327,0)),"")} -> 0 | M41: {=IFERROR(INDEX(Data_CT!P$2:P$327,MATCH($R$2&$R$1&$B41,Data_CT!$B$2:$B$327&Data_CT!$A$2:$A$327&Data_CT!$F$2:$F$327,0)),"")} | N41: {=IFERROR(INDEX(Data_CT!Q$2:Q$327,MATCH($R$2&$R$1&$B41,Data_CT!$B$2:$B$327&Data_CT!$A$2:$A$327&Data_CT!$F$2:$F$327,0)),"")} -> 0 | P41: {=IFERROR(INDEX(Data_CT!R$2:R$327,MATCH($R$2&$R$1&$B41,Data_CT!$B$2:$B$327&Data_CT!$A$2:$A$327&Data_CT!$F$2:$F$327,0)),"")} -> Mái Tầng 3
...

Sheet BC_SanLuong
A1: CÔNG TY CỔ PHẦN XÂY DỰNG NGÔ QUYỀN | H1: CỘNG HÒA XÃ HỘI CHỦ NGHĨA VIỆT NAM | Q1: Chọn tháng → | R1: 12
A2: BAN CHỈ HUY CÔNG TRƯỜNG | H2: Độc lập - Tự do - Hạnh phúc | Q2: Chọn năm → | R2: 2025
A3: ="BÁO CÁO SẢN LƯỢNG THÁNG "&R1 -> BÁO CÁO SẢN LƯỢNG THÁNG 12
A4: DỰ ÁN : KHU NHÀ Ở TẠI PHƯỜNG TRẠI CHUỐI
A5: ="THÁNG "&R1&" NĂM "&R2 -> THÁNG 12 NĂM 2025
A6: Đơn vị: đồng
A7: STT | B7: Danh mục | C7: Giá trị dự toán phần thô 2024 hoặc Quyết toán: | D7: Sản lượng kế hoạch | E7: Sản lượng thực hiện (xây thô) | G7: Sản lượng trát | H7: Tổng thô+trát | I7: Còn phải thực hiện | J7: Tỷ lệ hoàn thành (%) | L7: Ghi chú
E8: Kỳ này | F8: Lũy kế | J8: Kế hoạch kỳ này | K8: Tổng lũy kế
B9: 1 | C9: 2 | D9: 3 | E9: 4 | F9: 5 | G9: 6 | H9: 7=5+6 | I9: 8=2-5 | J9: 9 | K9: 10
A10: I | B10: Trại chuối GĐ 1
A11: A
A12: 1 | B12: Lô 5A | C12: {=IFERROR(INDEX(Data_SL!G$2:G$368,MATCH($R$2&$R$1&$B12,Data_SL!$B$2:$B$368&Data_SL!$A$2:$A$368&Data_SL!$F$2:$F$368,0)),"")} -> 1140788000 | D12: {=IFERROR(INDEX(Data_SL!H$2:H$368,MATCH($R$2&$R$1&$B12,Data_SL!$B$2:$B$368&Data_SL!$A$2:$A$368&Data_SL!$F$2:$F$368,0)),"")} -> 0 | E12: {=IFERROR(INDEX(Data_SL!I$2:I$368,MATCH($R$2&$R$1&$B12,Data_SL!$B$2:$B$368&Data_SL!$A$2:$A$368&Data_SL!$F$2:$F$368,0)),"")} -> 173974500 | F12: {=IFERROR(INDEX(Data_SL!J$2:J$368,MATCH($R$2&$R$1&$B12,Data_SL!$B$2:$B$368&Data_SL!$A$2:$A$368&Data_SL!$F$2:$F$368,0)),"")} -> 1027692225 | G12: {=IFERROR(INDEX(Data_SL!K$2:K$368,MATCH($R$2&$R$1&$B12,Data_SL!$B$2:$B$368&Data_SL!$A$2:$A$368&Data_SL!$F$2:$F$368,0)),"")} -> 0 | H12: {=IFERROR(INDEX(Data_SL!L$2:L$368,MATCH($R$2&$R$1&$B12,Data_SL!$B$2:$B$368&Data_SL!$A$2:$A$368&Data_SL!$F$2:$F$368,0)),"")} -> 1027692225 | I12: {=IFERROR(INDEX(Data_SL!M$2:M$368,MATCH($R$2&$R$1&$B12,Data_SL!$B$2:$B$368&Data_SL!$A$2:$A$368&Data_SL!$F$2:$F$368,0)),"")} -> 113095775 | J12: {=IFERROR(INDEX(Data_SL!N$2:N$368,MATCH($R$2&$R$1&$B12,Data_SL!$B$2:$B$368&Data_SL!$A$2:$A$368&Data_SL!$F$2:$F$368,0)),"")} -> 0 | ... L12: {=IFERROR(INDEX(Data_SL!P$2:P$368,MATCH($R$2&$R$1&$B12,Data_SL!$B$2:$B$368&Data_SL!$A$2:$A$368&Data_SL!$F$2:$F$368,0)),"")} -> 0
A13: 2 | B13: Lô 9A | C13: {=IFERROR(INDEX(Data_SL!G$2:G$368,MATCH($R$2&$R$1&$B13,Data_SL!$B$2:$B$368&Data_SL!$A$2:$A$368&Data_SL!$F$2:$F$368,0)),"")} -> 1118543000 | D13: {=IFERROR(INDEX(Data_SL!H$2:H$368,MATCH($R$2&$R$1&$B13,Data_SL!$B$2:$B$368&Data_SL!$A$2:$A$368&Data_SL!$F$2:$F$368,0)),"")} -> 0 | E13: {=IFERROR(INDEX(Data_SL!I$2:I$368,MATCH($R$2&$R$1&$B13,Data_SL!$B$2:$B$368&Data_SL!$A$2:$A$368&Data_SL!$F$2:$F$368,0)),"")} -> 0 | F13: {=IFERROR(INDEX(Data_SL!J$2:J$368,MATCH($R$2&$R$1&$B13,Data_SL!$B$2:$B$368&Data_SL!$A$2:$A$368&Data_SL!$F$2:$F$368,0)),"")} -> 1118543000 | G13: {=IFERROR(INDEX(Data_SL!K$2:K$368,MATCH($R$2&$R$1&$B13,Data_SL!$B$2:$B$368&Data_SL!$A$2:$A$368&Data_SL!$F$2:$F$368,0)),"")} -> 1.3825648e+08 | H13: {=IFERROR(INDEX(Data_SL!L$2:L$368,MATCH($R$2&$R$1&$B13,Data_SL!$B$2:$B$368&Data_SL!$A$2:$A$368&Data_SL!$F$2:$F$368,0)),"")} -> 1.2567995e+09 | I13: {=IFERROR(INDEX(Data_SL!M$2:M$368,MATCH($R$2&$R$1&$B13,Data_SL!$B$2:$B$368&Data_SL!$A$2:$A$368&Data_SL!$F$2:$F$368,0)),"")} -> 0 | J13: {=IFERROR(INDEX(Data_SL!N$2:N$368,MATCH($R$2&$R$1&$B13,Data_SL!$B$2:$B$368&Data_SL!$A$2:$A$368&Data_SL!$F$2:$F$368,0)),"")} -> 0 | ... L13: {=IFERROR(INDEX(Data_SL!P$2:P$368,MATCH($R$2&$R$1&$B13,Data_SL!$B$2:$B$368&Data_SL!$A$2:$A$368&Data_SL!$F$2:$F$368,0)),"")} -> Đã quyết toán | M13: =C13 -> 1118543000
A14: 3 | B14: Lô 12A | C14: {=IFERROR(INDEX(Data_SL!G$2:G$368,MATCH($R$2&$R$1&$B14,Data_SL!$B$2:$B$368&Data_SL!$A$2:$A$368&Data_SL!$F$2:$F$368,0)),"")} -> 1161338000 | D14: {=IFERROR(INDEX(Data_SL!H$2:H$368,MATCH($R$2&$R$1&$B14,Data_SL!$B$2:$B$368&Data_SL!$A$2:$A$368&Data_SL!$F$2:$F$368,0)),"")} -> 0 | E14: {=IFERROR(INDEX(Data_SL!I$2:I$368,MATCH($R$2&$R$1&$B14,Data_SL!$B$2:$B$368&Data_SL!$A$2:$A$368&Data_SL!$F$2:$F$368,0)),"")} -> 0 | F14: {=IFERROR(INDEX(Data_SL!J$2:J$368,MATCH($R$2&$R$1&$B14,Data_SL!$B$2:$B$368&Data_SL!$A$2:$A$368&Data_SL!$F$2:$F$368,0)),"")} -> 1161338000 | G14: {=IFERROR(INDEX(Data_SL!K$2:K$368,MATCH($R$2&$R$1&$B14,Data_SL!$B$2:$B$368&Data_SL!$A$2:$A$368&Data_SL!$F$2:$F$368,0)),"")} -> 28072222 | H14: {=IFERROR(INDEX(Data_SL!L$2:L$368,MATCH($R$2&$R$1&$B14,Data_SL!$B$2:$B$368&Data_SL!$A$2:$A$368&Data_SL!$F$2:$F$368,0)),"")} -> 1.1894102e+09 | I14: {=IFERROR(INDEX(Data_SL!M$2:M$368,MATCH($R$2&$R$1&$B14,Data_SL!$B$2:$B$368&Data_SL!$A$2:$A$368&Data_SL!$F$2:$F$368,0)),"")} -> 0 | J14: {=IFERROR(INDEX(Data_SL!N$2:N$368,MATCH($R$2&$R$1&$B14,Data_SL!$B$2:$B$368&Data_SL!$A$2:$A$368&Data_SL!$F$2:$F$368,0)),"")} -> 0 | ... L14: {=IFERROR(INDEX(Data_SL!P$2:P$368,MATCH($R$2&$R$1&$B14,Data_SL!$B$2:$B$368&Data_SL!$A$2:$A$368&Data_SL!$F$2:$F$368,0)),"")} -> Đã quyết toán | M14: =C14 -> 1161338000
A15: 4 | B15: Lô 13A | C15: {=IFERROR(INDEX(Data_SL!G$2:G$368,MATCH($R$2&$R$1&$B15,Data_SL!$B$2:$B$368&Data_SL!$A$2:$A$368&Data_SL!$F$2:$F$368,0)),"")} -> 1129099000 | D15: {=IFERROR(INDEX(Data_SL!H$2:H$368,MATCH($R$2&$R$1&$B15,Data_SL!$B$2:$B$368&Data_SL!$A$2:$A$368&Data_SL!$F$2:$F$368,0)),"")} -> 0 | E15: {=IFERROR(INDEX(Data_SL!I$2:I$368,MATCH($R$2&$R$1&$B15,Data_SL!$B$2:$B$368&Data_SL!$A$2:$A$368&Data_SL!$F$2:$F$368,0)),"")} -> 186300000 | F15: {=IFERROR(INDEX(Data_SL!J$2:J$368,MATCH($R$2&$R$1&$B15,Data_SL!$B$2:$B$368&Data_SL!$A$2:$A$368&Data_SL!$F$2:$F$368,0)),"")} -> 675697680 | G15: {=IFERROR(INDEX(Data_SL!K$2:K$368,MATCH($R$2&$R$1&$B15,Data_SL!$B$2:$B$368&Data_SL!$A$2:$A$368&Data_SL!$F$2:$F$368,0)),"")} -> 0 | H15: {=IFERROR(INDEX(Data_SL!L$2:L$368,MATCH($R$2&$R$1&$B15,Data_SL!$B$2:$B$368&Data_SL!$A$2:$A$368&Data_SL!$F$2:$F$368,0)),"")} -> 675697680 | I15: {=IFERROR(INDEX(Data_SL!M$2:M$368,MATCH($R$2&$R$1&$B15,Data_SL!$B$2:$B$368&Data_SL!$A$2:$A$368&Data_SL!$F$2:$F$368,0)),"")} -> 453401320 | J15: {=IFERROR(INDEX(Data_SL!N$2:N$368,MATCH($R$2&$R$1&$B15,Data_SL!$B$2:$B$368&Data_SL!$A$2:$A$368&Data_SL!$F$2:$F$368,0)),"")} -> 0 | ... L15: {=IFERROR(INDEX(Data_SL!P$2:P$368,MATCH($R$2&$R$1&$B15,Data_SL!$B$2:$B$368&Data_SL!$A$2:$A$368&Data_SL!$F$2:$F$368,0)),"")} -> 0
A16: 5 | B16: Lô 14A | C16: {=IFERROR(INDEX(Data_SL!G$2:G$368,MATCH($R$2&$R$1&$B16,Data_SL!$B$2:$B$368&Data_SL!$A$2:$A$368&Data_SL!$F$2:$F$368,0)),"")} -> 1129099000 | D16: {=IFERROR(INDEX(Data_SL!H$2:H$368,MATCH($R$2&$R$1&$B16,Data_SL!$B$2:$B$368&Data_SL!$A$2:$A$368&Data_SL!$F$2:$F$368,0)),"")} -> 0 | E16: {=IFERROR(INDEX(Data_SL!I$2:I$368,MATCH($R$2&$R$1&$B16,Data_SL!$B$2:$B$368&Data_SL!$A$2:$A$368&Data_SL!$F$2:$F$368,0)),"")} -> 0 | F16: {=IFERROR(INDEX(Data_SL!J$2:J$368,MATCH($R$2&$R$1&$B16,Data_SL!$B$2:$B$368&Data_SL!$A$2:$A$368&Data_SL!$F$2:$F$368,0)),"")} -> 649826280 | G16: {=IFERROR(INDEX(Data_SL!K$2:K$368,MATCH($R$2&$R$1&$B16,Data_SL!$B$2:$B$368&Data_SL!$A$2:$A$368&Data_SL!$F$2:$F$368,0)),"")} -> 0 | H16: {=IFERROR(INDEX(Data_SL!L$2:L$368,MATCH($R$2&$R$1&$B16,Data_SL!$B$2:$B$368&Data_SL!$A$2:$A$368&Data_SL!$F$2:$F$368,0)),"")} -> 649826280 | I16: {=IFERROR(INDEX(Data_SL!M$2:M$368,MATCH($R$2&$R$1&$B16,Data_SL!$B$2:$B$368&Data_SL!$A$2:$A$368&Data_SL!$F$2:$F$368,0)),"")} -> 479272720 | J16: {=IFERROR(INDEX(Data_SL!N$2:N$368,MATCH($R$2&$R$1&$B16,Data_SL!$B$2:$B$368&Data_SL!$A$2:$A$368&Data_SL!$F$2:$F$368,0)),"")} -> 0 | ... L16: {=IFERROR(INDEX(Data_SL!P$2:P$368,MATCH($R$2&$R$1&$B16,Data_SL!$B$2:$B$368&Data_SL!$A$2:$A$368&Data_SL!$F$2:$F$368,0)),"")} -> Tạm dừng thi công | M16: =ROUND(13.806*4,3) -> 55.224 | N16: 4500000 | O16: =ROUND(M16*N16,3) -> 248508000 | P16: =O16*0.55 -> 136679400 | Q16: =O16*0.45 -> 111828600
A17: B | I17: =G17+H17 -> 0 | M17: 0
A18: 1 | B18: Lô 1B | C18: {=IFERROR(INDEX(Data_SL!G$2:G$368,MATCH($R$2&$R$1&$B18,Data_SL!$B$2:$B$368&Data_SL!$A$2:$A$368&Data_SL!$F$2:$F$368,0)),"")} -> 1295727000 | D18: {=IFERROR(INDEX(Data_SL!H$2:H$368,MATCH($R$2&$R$1&$B18,Data_SL!$B$2:$B$368&Data_SL!$A$2:$A$368&Data_SL!$F$2:$F$368,0)),"")} -> 0 | E18: {=IFERROR(INDEX(Data_SL!I$2:I$368,MATCH($R$2&$R$1&$B18,Data_SL!$B$2:$B$368&Data_SL!$A$2:$A$368&Data_SL!$F$2:$F$368,0)),"")} -> 0 | F18: {=IFERROR(INDEX(Data_SL!J$2:J$368,MATCH($R$2&$R$1&$B18,Data_SL!$B$2:$B$368&Data_SL!$A$2:$A$368&Data_SL!$F$2:$F$368,0)),"")} -> 1295727000 | G18: {=IFERROR(INDEX(Data_SL!K$2:K$368,MATCH($R$2&$R$1&$B18,Data_SL!$B$2:$B$368&Data_SL!$A$2:$A$368&Data_SL!$F$2:$F$368,0)),"")} -> 205662963 | H18: {=IFERROR(INDEX(Data_SL!L$2:L$368,MATCH($R$2&$R$1&$B18,Data_SL!$B$2:$B$368&Data_SL!$A$2:$A$368&Data_SL!$F$2:$F$368,0)),"")} -> 1501389963 | I18: {=IFERROR(INDEX(Data_SL!M$2:M$368,MATCH($R$2&$R$1&$B18,Data_SL!$B$2:$B$368&Data_SL!$A$2:$A$368&Data_SL!$F$2:$F$368,0)),"")} -> 0 | J18: {=IFERROR(INDEX(Data_SL!N$2:N$368,MATCH($R$2&$R$1&$B18,Data_SL!$B$2:$B$368&Data_SL!$A$2:$A$368&Data_SL!$F$2:$F$368,0)),"")} -> 0 | ... L18: {=IFERROR(INDEX(Data_SL!P$2:P$368,MATCH($R$2&$R$1&$B18,Data_SL!$B$2:$B$368&Data_SL!$A$2:$A$368&Data_SL!$F$2:$F$368,0)),"")} -> Đã quyết toán | M18: 1209628000
A19: =A18+1 -> 2 | B19: Lô 3B | C19: {=IFERROR(INDEX(Data_SL!G$2:G$368,MATCH($R$2&$R$1&$B19,Data_SL!$B$2:$B$368&Data_SL!$A$2:$A$368&Data_SL!$F$2:$F$368,0)),"")} -> 1629894000 | D19: {=IFERROR(INDEX(Data_SL!H$2:H$368,MATCH($R$2&$R$1&$B19,Data_SL!$B$2:$B$368&Data_SL!$A$2:$A$368&Data_SL!$F$2:$F$368,0)),"")} -> 0 | E19: {=IFERROR(INDEX(Data_SL!I$2:I$368,MATCH($R$2&$R$1&$B19,Data_SL!$B$2:$B$368&Data_SL!$A$2:$A$368&Data_SL!$F$2:$F$368,0)),"")} -> 0 | F19: {=IFERROR(INDEX(Data_SL!J$2:J$368,MATCH($R$2&$R$1&$B19,Data_SL!$B$2:$B$368&Data_SL!$A$2:$A$368&Data_SL!$F$2:$F$368,0)),"")} -> 1629894000 | G19: {=IFERROR(INDEX(Data_SL!K$2:K$368,MATCH($R$2&$R$1&$B19,Data_SL!$B$2:$B$368&Data_SL!$A$2:$A$368&Data_SL!$F$2:$F$368,0)),"")} -> 1.3494444e+08 | H19: {=IFERROR(INDEX(Data_SL!L$2:L$368,MATCH($R$2&$R$1&$B19,Data_SL!$B$2:$B$368&Data_SL!$A$2:$A$368&Data_SL!$F$2:$F$368,0)),"")} -> 1.7648384e+09 | I19: {=IFERROR(INDEX(Data_SL!M$2:M$368,MATCH($R$2&$R$1&$B19,Data_SL!$B$2:$B$368&Data_SL!$A$2:$A$368&Data_SL!$F$2:$F$368,0)),"")} -> 0 | J19: {=IFERROR(INDEX(Data_SL!N$2:N$368,MATCH($R$2&$R$1&$B19,Data_SL!$B$2:$B$368&Data_SL!$A$2:$A$368&Data_SL!$F$2:$F$368,0)),"")} -> 0 | ... L19: {=IFERROR(INDEX(Data_SL!P$2:P$368,MATCH($R$2&$R$1&$B19,Data_SL!$B$2:$B$368&Data_SL!$A$2:$A$368&Data_SL!$F$2:$F$368,0)),"")} -> Đã quyết toán | M19: =C19 -> 1629894000
A20: =A19+1 -> 3 | B20: Lô 4B | C20: {=IFERROR(INDEX(Data_SL!G$2:G$368,MATCH($R$2&$R$1&$B20,Data_SL!$B$2:$B$368&Data_SL!$A$2:$A$368&Data_SL!$F$2:$F$368,0)),"")} -> 1323642000 | D20: {=IFERROR(INDEX(Data_SL!H$2:H$368,MATCH($R$2&$R$1&$B20,Data_SL!$B$2:$B$368&Data_SL!$A$2:$A$368&Data_SL!$F$2:$F$368,0)),"")} -> 0 | E20: {=IFERROR(INDEX(Data_SL!I$2:I$368,MATCH($R$2&$R$1&$B20,Data_SL!$B$2:$B$368&Data_SL!$A$2:$A$368&Data_SL!$F$2:$F$368,0)),"")} -> 0 | F20: {=IFERROR(INDEX(Data_SL!J$2:J$368,MATCH($R$2&$R$1&$B20,Data_SL!$B$2:$B$368&Data_SL!$A$2:$A$368&Data_SL!$F$2:$F$368,0)),"")} -> 1323642000 | G20: {=IFERROR(INDEX(Data_SL!K$2:K$368,MATCH($R$2&$R$1&$B20,Data_SL!$B$2:$B$368&Data_SL!$A$2:$A$368&Data_SL!$F$2:$F$368,0)),"")} -> 0 | H20: {=IFERROR(INDEX(Data_SL!L$2:L$368,MATCH($R$2&$R$1&$B20,Data_SL!$B$2:$B$368&Data_SL!$A$2:$A$368&Data_SL!$F$2:$F$368,0)),"")} -> 1323642000 | I20: {=IFERROR(INDEX(Data_SL!M$2:M$368,MATCH($R$2&$R$1&$B20,Data_SL!$B$2:$B$368&Data_SL!$A$2:$A$368&Data_SL!$F$2:$F$368,0)),"")} -> 0 | J20: {=IFERROR(INDEX(Data_SL!N$2:N$368,MATCH($R$2&$R$1&$B20,Data_SL!$B$2:$B$368&Data_SL!$A$2:$A$368&Data_SL!$F$2:$F$368,0)),"")} -> 0 | ... L20: {=IFERROR(INDEX(Data_SL!P$2:P$368,MATCH($R$2&$R$1&$B20,Data_SL!$B$2:$B$368&Data_SL!$A$2:$A$368&Data_SL!$F$2:$F$368,0)),"")} -> 0 | M20: 0
